Workbook

Sheet 說明
A1: 項目 | B1: 內容
A2: 已完成配準資料集數 | B2: 1
A3: 已完成配準資料集 | B3: ETH-Trees
A4: 跨資料集配準狀態 | B4: 尚未完成：其他原始站點與配準真值待取得
A5: 外部樹木提取驗證 | B5: Liang2018 / TreeTool處理後六樣區、三設定、seed11–20；見外部提取工作表
A6: 本輪ETH的seed | B6: 11–20；篩選使用舊seed1–5，6–10另列
A7: 成功定義 | B7: 旋轉誤差 < 2° 且平移誤差 < 0.5 m
A8: 兩站方法 | B8: 每次只用兩站；控制組5 cm＋SVD，候選為固定10 cm＋配準RANSAC
A9: 多站方法 | B9: 最大生成樹使用同場景全部站；與獨立兩站任務分開解讀
A10: e_p定義 | B10: source全部點的平均變換差；表內中位數只對成功案例
A11: 新資料策略 | B11: 使用ETH固定參數直接套用，不先針對新資料重調
A12: ETH建議 | B12: 獨立兩站優先10cm＋配準RANSAC：142/150 (94.7%)；control SVD為118/150 (78.7%)
A13: 多站路徑建議 | B13: 六站最大生成樹150/150；需取得全部站點，不與獨立兩站作相同條件宣稱
A14: 資料缺漏 | B14: 未下載／未執行列明確標示；不是0%成功率
... A18: 後續優先順序 | B18: 取得原始分站資料與配準真值，驗證固定10cm＋配準RANSAC；提取先檢查漏樹原因、感測器原點與標註範圍。

Sheet 逐對結果
A1: 資料集 | B1: 場景 | C1: 任務 | D1: 方法代碼 | E1: solver | F1: seed | G1: pair | H1: 官方配對 | I1: 求得變換 | J1: 成功 | K1: 旋轉誤差° | L1: 平移誤差m | M1: e_p m | N1: CN匹配數 | O1: GT正確匹配數(僅評分) | P1: RANSAC inliers | Q1: 多站路徑 | R1: 匹配＋求解ms | S1: 擷取設定 | T1: 結果來源
A2: ETH-Trees | B2: Trees | C2: 兩站 | D2: fresh_control | E2: svd | F2: 11 | G2: s1-s2 | H2: 1 | I2: 1 | J2: 1 | K2: 0.54773544 | L2: 0.080279404 | M2: 0.087026289 | N2: 6 | O2: 6 | P2: 0 | R2: 1.713854 | S2: control | T2: results/eth_trees/tuning_20261025/runs/fresh_rows.csv
A3: ETH-Trees | B3: Trees | C3: 兩站 | D3: fresh_control | E3: svd+ransac | F3: 11 | G3: s1-s2 | H3: 1 | I3: 1 | J3: 1 | K3: 0.54773544 | L3: 0.080279404 | M3: 0.087026289 | N3: 6 | O3: 6 | P3: 6 | R3: 6.131956 | S3: control | T3: results/eth_trees/tuning_20261025/runs/fresh_rows.csv
A4: ETH-Trees | B4: Trees | C4: 兩站 | D4: fresh_control | E4: svd | F4: 11 | G4: s1-s3 | H4: 1 | I4: 1 | J4: 1 | K4: 1.7622011 | L4: 0.27435017 | M4: 0.28907962 | N4: 9 | O4: 9 | P4: 0 | R4: 1.415102 | S4: control | T4: results/eth_trees/tuning_20261025/runs/fresh_rows.csv
A5: ETH-Trees | B5: Trees | C5: 兩站 | D5: fresh_control | E5: svd+ransac | F5: 11 | G5: s1-s3 | H5: 1 | I5: 1 | J5: 1 | K5: 1.2683517 | L5: 0.10658032 | M5: 0.1281766 | N5: 9 | O5: 9 | P5: 8 | R5: 1.925898 | S5: control | T5: results/eth_trees/tuning_20261025/runs/fresh_rows.csv
A6: ETH-Trees | B6: Trees | C6: 兩站 | D6: fresh_control | E6: svd | F6: 11 | G6: s1-s4 | H6: 0 | I6: 1 | J6: 1 | K6: 0.99967114 | L6: 0.20461008 | M6: 0.21323552 | N6: 6 | O6: 6 | P6: 0 | R6: 5.426543 | S6: control | T6: results/eth_trees/tuning_20261025/runs/fresh_rows.csv
A7: ETH-Trees | B7: Trees | C7: 兩站 | D7: fresh_control | E7: svd+ransac | F7: 11 | G7: s1-s4 | H7: 0 | I7: 1 | J7: 1 | K7: 0.99967114 | L7: 0.20461008 | M7: 0.21323552 | N7: 6 | O7: 6 | P7: 6 | R7: 5.859021 | S7: control | T7: results/eth_trees/tuning_20261025/runs/fresh_rows.csv
A8: ETH-Trees | B8: Trees | C8: 兩站 | D8: fresh_control | E8: svd | F8: 11 | G8: s1-s5 | H8: 0 | I8: 1 | J8: 0 | K8: 2.0161573 | L8: 0.5794676 | M8: 0.58740625 | N8: 6 | O8: 6 | P8: 0 | R8: 2.41501 | S8: control | T8: results/eth_trees/tuning_20261025/runs/fresh_rows.csv
A9: ETH-Trees | B9: Trees | C9: 兩站 | D9: fresh_control | E9: svd+ransac | F9: 11 | G9: s1-s5 | H9: 0 | I9: 1 | J9: 1 | K9: 0.52907802 | L9: 0.10110078 | M9: 0.10449931 | N9: 6 | O9: 6 | P9: 5 | R9: 6.990876 | S9: control | T9: results/eth_trees/tuning_20261025/runs/fresh_rows.csv
A10: ETH-Trees | B10: Trees | C10: 兩站 | D10: fresh_control | E10: svd | F10: 11 | G10: s1-s6 | H10: 0 | I10: 1 | J10: 0 | K10: 8.5544613 | L10: 3.6936636 | M10: 3.6760071 | N10: 3 | O10: 3 | P10: 0 | R10: 2.437844 | S10: control | T10: results/eth_trees/tuning_20261025/runs/fresh_rows.csv
A11: ETH-Trees | B11: Trees | C11: 兩站 | D11: fresh_control | E11: svd+ransac | F11: 11 | G11: s1-s6 | H11: 0 | I11: 1 | J11: 0 | K11: 8.5544613 | L11: 3.6936636 | M11: 3.6760071 | N11: 3 | O11: 3 | P11: 3 | R11: 2.618301 | S11: control | T11: results/eth_trees/tuning_20261025/runs/fresh_rows.csv
A12: ETH-Trees | B12: Trees | C12: 兩站 | D12: fresh_control | E12: svd | F12: 12 | G12: s1-s2 | H12: 1 | I12: 1 | J12: 1 | K12: 0.43836989 | L12: 0.062225384 | M12: 0.067612733 | N12: 6 | O12: 6 | P12: 0 | R12: 1.57599 | S12: control | T12: results/eth_trees/tuning_20261025/runs/fresh_rows.csv
A13: ETH-Trees | B13: Trees | C13: 兩站 | D13: fresh_control | E13: svd+ransac | F13: 12 | G13: s1-s2 | H13: 1 | I13: 1 | J13: 1 | K13: 0.43836989 | L13: 0.062225384 | M13: 0.067612733 | N13: 6 | O13: 6 | P13: 6 | R13: 1.952296 | S13: control | T13: results/eth_trees/tuning_20261025/runs/fresh_rows.csv
... A29: ETH-Trees | B29: Trees | C29: 兩站 | D29: fresh_control | E29: svd+ransac | F29: 13 | G29: s1-s5 | H29: 0 | I29: 1 | J29: 1 | K29: 0.48208598 | L29: 0.10782001 | M29: 0.11181077 | N29: 5 | O29: 5 | P29: 5 | R29: 6.569632 | S29: control | T29: results/eth_trees/tuning_20261025/runs/fresh_rows.csv
A30: ETH-Trees | B30: Trees | C30: 兩站 | D30: fresh_control | E30: svd | F30: 13 | G30: s1-s6 | H30: 0 | I30: 0 | J30: 0 | N30: 0 | O30: 0 | P30: 0 | R30: 2.129048 | S30: control | T30: results/eth_trees/tuning_20261025/runs/fresh_rows.csv
A31: ETH-Trees | B31: Trees | C31: 兩站 | D31: fresh_control | E31: svd+ransac | F31: 13 | G31: s1-s6 | H31: 0 | I31: 0 | J31: 0 | N31: 0 | O31: 0 | P31: 0 | R31: 2.128918 | S31: control | T31: results/eth_trees/tuning_20261025/runs/fresh_rows.csv
A32: ETH-Trees | B32: Trees | C32: 兩站 | D32: fresh_control | E32: svd | F32: 14 | G32: s1-s2 | H32: 1 | I32: 0 | J32: 0 | N32: 2 | O32: 2 | P32: 0 | R32: 5.402709 | S32: control | T32: results/eth_trees/tuning_20261025/runs/fresh_rows.csv
A33: ETH-Trees | B33: Trees | C33: 兩站 | D33: fresh_control | E33: svd+ransac | F33: 14 | G33: s1-s2 | H33: 1 | I33: 0 | J33: 0 | N33: 2 | O33: 2 | P33: 0 | R33: 5.402749 | S33: control | T33: results/eth_trees/tuning_20261025/runs/fresh_rows.csv
A34: ETH-Trees | B34: Trees | C34: 兩站 | D34: fresh_control | E34: svd | F34: 14 | G34: s1-s3 | H34: 1 | I34: 1 | J34: 1 | K34: 1.1381519 | L34: 0.12730976 | M34: 0.14290071 | N34: 9 | O34: 9 | P34: 0 | R34: 1.25142 | S34: control | T34: results/eth_trees/tuning_20261025/runs/fresh_rows.csv
A35: ETH-Trees | B35: Trees | C35: 兩站 | D35: fresh_control | E35: svd+ransac | F35: 14 | G35: s1-s3 | H35: 1 | I35: 1 | J35: 1 | K35: 1.1381519 | L35: 0.12730976 | M35: 0.14290071 | N35: 9 | O35: 9 | P35: 9 | R35: 1.789976 | S35: control | T35: results/eth_trees/tuning_20261025/runs/fresh_rows.csv
A36: ETH-Trees | B36: Trees | C36: 兩站 | D36: fresh_control | E36: svd | F36: 14 | G36: s1-s4 | H36: 0 | I36: 0 | J36: 0 | N36: 2 | O36: 2 | P36: 0 | R36: 1.52806 | S36: control | T36: results/eth_trees/tuning_20261025/runs/fresh_rows.csv
A37: ETH-Trees | B37: Trees | C37: 兩站 | D37: fresh_control | E37: svd+ransac | F37: 14 | G37: s1-s4 | H37: 0 | I37: 0 | J37: 0 | N37: 2 | O37: 2 | P37: 0 | R37: 1.527999 | S37: control | T37: results/eth_trees/tuning_20261025/runs/fresh_rows.csv
A38: ETH-Trees | B38: Trees | C38: 兩站 | D38: fresh_control | E38: svd | F38: 14 | G38: s1-s5 | H38: 0 | I38: 1 | J38: 1 | K38: 0.82723443 | L38: 0.23565572 | M38: 0.24105911 | N38: 3 | O38: 3 | P38: 0 | R38: 6.3309 | S38: control | T38: results/eth_trees/tuning_20261025/runs/fresh_rows.csv
A39: ETH-Trees | B39: Trees | C39: 兩站 | D39: fresh_control | E39: svd+ransac | F39: 14 | G39: s1-s5 | H39: 0 | I39: 1 | J39: 1 | K39: 0.82723443 | L39: 0.23565572 | M39: 0.24105911 | N39: 3 | O39: 3 | P39: 3 | R39: 6.50681 | S39: control | T39: results/eth_trees/tuning_20261025/runs/fresh_rows.csv
A40: ETH-Trees | B40: Trees | C40: 兩站 | D40: fresh_control | E40: svd | F40: 14 | G40: s1-s6 | H40: 0 | I40: 1 | J40: 0 | K40: 3.9642737 | L40: 0.21201757 | M40: 0.31424586 | N40: 4 | O40: 4 | P40: 0 | R40: 2.591262 | S40: control | T40: results/eth_trees/tuning_20261025/runs/fresh_rows.csv
A41: ETH-Trees | B41: Trees | C41: 兩站 | D41: fresh_control | E41: svd+ransac | F41: 14 | G41: s1-s6 | H41: 0 | I41: 1 | J41: 1 | K41: 1.8186896 | L41: 0.13551499 | M41: 0.17730392 | N41: 4 | O41: 4 | P41: 3 | R41: 2.896703 | S41: control | T41: results/eth_trees/tuning_20261025/runs/fresh_rows.csv
A42: ETH-Trees | B42: Trees | C42: 兩站 | D42: fresh_control | E42: svd | F42: 15 | G42: s1-s2 | H42: 1 | I42: 1 | J42: 1 | K42: 0.47692242 | L42: 0.10941369 | M42: 0.1185239 | N42: 5 | O42: 5 | P42: 0 | R42: 5.481524 | S42: control | T42: results/eth_trees/tuning_20261025/runs/fresh_rows.csv
A43: ETH-Trees | B43: Trees | C43: 兩站 | D43: fresh_control | E43: svd+ransac | F43: 15 | G43: s1-s2 | H43: 1 | I43: 1 | J43: 1 | K43: 0.47692242 | L43: 0.10941369 | M43: 0.1185239 | N43: 5 | O43: 5 | P43: 5 | R43: 5.847985 | S43: control | T43: results/eth_trees/tuning_20261025/runs/fresh_rows.csv
A44: ETH-Trees | B44: Trees | C44: 兩站 | D44: fresh_control | E44: svd | F44: 15 | G44: s1-s3 | H44: 1 | I44: 1 | J44: 1 | K44: 0.36357182 | L44: 0.03498049 | M44: 0.040713536 | N44: 10 | O44: 10 | P44: 0 | R44: 1.435792 | S44: control | T44: results/eth_trees/tuning_20261025/runs/fresh_rows.csv
A45: ETH-Trees | B45: Trees | C45: 兩站 | D45: fresh_control | E45: svd+ransac | F45: 15 | G45: s1-s3 | H45: 1 | I45: 1 | J45: 1 | K45: 0.36357182 | L45: 0.03498049 | M45: 0.040713536 | N45: 10 | O45: 10 | P45: 10 | R45: 2.022249 | S45: control | T45: results/eth_trees/tuning_20261025/runs/fresh_rows.csv
A46: ETH-Trees | B46: Trees | C46: 兩站 | D46: fresh_control | E46: svd | F46: 15 | G46: s1-s4 | H46: 0 | I46: 0 | J46: 0 | N46: 1 | O46: 1 | P46: 0 | R46: 1.260484 | S46: control | T46: results/eth_trees/tuning_20261025/runs/fresh_rows.csv
A47: ETH-Trees | B47: Trees | C47: 兩站 | D47: fresh_control | E47: svd+ransac | F47: 15 | G47: s1-s4 | H47: 0 | I47: 0 | J47: 0 | N47: 1 | O47: 1 | P47: 0 | R47: 1.260634 | S47: control | T47: results/eth_trees/tuning_20261025/runs/fresh_rows.csv
A48: ETH-Trees | B48: Trees | C48: 兩站 | D48: fresh_control | E48: svd | F48: 15 | G48: s1-s5 | H48: 0 | I48: 1 | J48: 1 | K48: 0.85802265 | L48: 0.31298172 | M48: 0.3151043 | N48: 5 | O48: 5 | P48: 0 | R48: 2.165771 | S48: control | T48: results/eth_trees/tuning_20261025/runs/fresh_rows.csv
A49: ETH-Trees | B49: Trees | C49: 兩站 | D49: fresh_control | E49: svd+ransac | F49: 15 | G49: s1-s5 | H49: 0 | I49: 1 | J49: 1 | K49: 0.85802265 | L49: 0.31298172 | M49: 0.3151043 | N49: 5 | O49: 5 | P49: 5 | R49: 2.560925 | S49: control | T49: results/eth_trees/tuning_20261025/runs/fresh_rows.csv
A50: ETH-Trees | B50: Trees | C50: 兩站 | D50: fresh_control | E50: svd | F50: 15 | G50: s1-s6 | H50: 0 | I50: 1 | J50: 1 | K50: 1.3779078 | L50: 0.091204314 | M50: 0.1241737 | N50: 6 | O50: 6 | P50: 0 | R50: 2.235886 | S50: control | T50: results/eth_trees/tuning_20261025/runs/fresh_rows.csv
A51: ETH-Trees | B51: Trees | C51: 兩站 | D51: fresh_control | E51: svd+ransac | F51: 15 | G51: s1-s6 | H51: 0 | I51: 1 | J51: 1 | K51: 1.3779078 | L51: 0.091204314 | M51: 0.1241737 | N51: 6 | O51: 6 | P51: 6 | R51: 2.663769 | S51: control | T51: results/eth_trees/tuning_20261025/runs/fresh_rows.csv
A52: ETH-Trees | B52: Trees | C52: 兩站 | D52: fresh_control | E52: svd | F52: 16 | G52: s1-s2 | H52: 1 | I52: 1 | J52: 1 | K52: 0.36539857 | L52: 0.062431004 | M52: 0.065425177 | N52: 8 | O52: 8 | P52: 0 | R52: 1.471125 | S52: control | T52: results/eth_trees/tuning_20261025/runs/fresh_rows.csv
A53: ETH-Trees | B53: Trees | C53: 兩站 | D53: fresh_control | E53: svd+ransac | F53: 16 | G53: s1-s2 | H53: 1 | I53: 1 | J53: 1 | K53: 0.36539857 | L53: 0.062431004 | M53: 0.065425177 | N53: 8 | O53: 8 | P53: 8 | R53: 27.193963 | S53: control | T53: results/eth_trees/tuning_20261025/runs/fresh_rows.csv
A54: ETH-Trees | B54: Trees | C54: 兩站 | D54: fresh_control | E54: svd | F54: 16 | G54: s1-s3 | H54: 1 | I54: 1 | J54: 1 | K54: 0.71665337 | L54: 0.051892073 | M54: 0.065147149 | N54: 10 | O54: 10 | P54: 0 | R54: 1.220675 | S54: control | T54: results/eth_trees/tuning_20261025/runs/fresh_rows.csv
A55: ETH-Trees | B55: Trees | C55: 兩站 | D55: fresh_control | E55: svd+ransac | F55: 16 | G55: s1-s3 | H55: 1 | I55: 1 | J55: 1 | K55: 0.71665337 | L55: 0.051892073 | M55: 0.065147149 | N55: 10 | O55: 10 | P55: 10 | R55: 1.818559 | S55: control | T55: results/eth_trees/tuning_20261025/runs/fresh_rows.csv
...

Sheet 估計變換
A1: 資料集 | B1: 方法代碼 | C1: solver | D1: seed | E1: source | F1: target | G1: 求得變換 | H1: r00 | I1: r01 | J1: r02 | K1: r10 | L1: r11 | M1: r12 | N1: r20 | O1: r21 | P1: r22 | Q1: t0 | R1: t1 | S1: t2
A2: ETH-Trees | B2: fresh_control | C2: svd | D2: 11 | E2: s1 | F2: s2 | G2: 1 | H2: -0.71809643 | I2: -0.69587985 | J2: 0.0094205368 | K2: 0.69585934 | L2: -0.71815434 | M2: -0.0058411735 | N2: 0.010830154 | O2: 0.0023608427 | P2: 0.99993857 | Q2: -11.080821 | R2: -0.86532821 | S2: 0.61850745
A3: ETH-Trees | B3: fresh_control | C3: svd+ransac | D3: 11 | E3: s1 | F3: s2 | G3: 1 | H3: -0.71809643 | I3: -0.69587985 | J3: 0.0094205368 | K3: 0.69585934 | L3: -0.71815434 | M3: -0.0058411735 | N3: 0.010830154 | O3: 0.0023608427 | P3: 0.99993857 | Q3: -11.080821 | R3: -0.86532821 | S3: 0.61850745
A4: ETH-Trees | B4: fresh_control | C4: svd | D4: 11 | E4: s1 | F4: s3 | G4: 1 | H4: 0.93337108 | I4: 0.35801394 | J4: -0.025386019 | K4: -0.35776368 | L4: 0.93370793 | M4: 0.01395171 | N4: 0.028698034 | O4: -0.0039399265 | P4: 0.99958036 | Q4: 8.3258764 | R4: 1.3955839 | S4: 0.92679116
A5: ETH-Trees | B5: fresh_control | C5: svd+ransac | D5: 11 | E5: s1 | F5: s3 | G5: 1 | H5: 0.93355627 | I5: 0.35819461 | J5: -0.01301212 | K5: -0.35799487 | L5: 0.93359611 | M5: 0.015426743 | N5: 0.017673841 | O5: -0.0097434606 | P5: 0.99979633 | Q5: 8.3670479 | R5: 1.3946954 | S5: 0.75988866
A6: ETH-Trees | B6: fresh_control | C6: svd | D6: 11 | E6: s1 | F6: s4 | G6: 1 | H6: 0.90264076 | I6: 0.43014218 | J6: -0.014743613 | K6: -0.43028024 | L6: 0.90266117 | M6: -0.0078571637 | N6: 0.0099287892 | O6: 0.013436081 | P6: 0.99986044 | Q6: 22.822959 | R6: 6.5478754 | S6: 1.6022451
A7: ETH-Trees | B7: fresh_control | C7: svd+ransac | D7: 11 | E7: s1 | F7: s4 | G7: 1 | H7: 0.90264076 | I7: 0.43014218 | J7: -0.014743613 | K7: -0.43028024 | L7: 0.90266117 | M7: -0.0078571637 | N7: 0.0099287892 | O7: 0.013436081 | P7: 0.99986044 | Q7: 22.822959 | R7: 6.5478754 | S7: 1.6022451
A8: ETH-Trees | B8: fresh_control | C8: svd | D8: 11 | E8: s1 | F8: s5 | G8: 1 | H8: 0.22340877 | I8: -0.97460739 | J8: 0.015131158 | K8: 0.97427478 | L8: 0.22280701 | M8: -0.033848102 | N8: 0.029617283 | O8: 0.022303868 | P8: 0.99931244 | Q8: -16.532613 | R8: 20.417667 | S8: 1.5662435
A9: ETH-Trees | B9: fresh_control | C9: svd+ransac | D9: 11 | E9: s1 | F9: s5 | G9: 1 | H9: 0.22574444 | I9: -0.97418654 | J9: -0.0002028874 | K9: 0.97412973 | L9: 0.22573351 | M9: -0.010753751 | N9: 0.010521958 | O9: 0.0022299609 | P9: 0.99994216 | Q9: -16.526495 | R9: 20.514996 | S9: 1.0965589
A10: ETH-Trees | B10: fresh_control | C10: svd | D10: 11 | E10: s1 | F10: s6 | G10: 1 | H10: 0.97485781 | I10: 0.16627193 | J10: 0.14834387 | K10: -0.16669896 | L10: 0.98596073 | M10: -0.0096385291 | N10: -0.14786385 | O10: -0.015332573 | P10: 0.98888887 | Q10: 25.677231 | R10: 19.32466 | S10: -1.5353695
A11: ETH-Trees | B11: fresh_control | C11: svd+ransac | D11: 11 | E11: s1 | F11: s6 | G11: 1 | H11: 0.97485781 | I11: 0.16627193 | J11: 0.14834387 | K11: -0.16669896 | L11: 0.98596073 | M11: -0.0096385291 | N11: -0.14786385 | O11: -0.015332573 | P11: 0.98888887 | Q11: 25.677231 | R11: 19.32466 | S11: -1.5353695
A12: ETH-Trees | B12: fresh_control | C12: svd | D12: 12 | E12: s1 | F12: s2 | G12: 1 | H12: -0.71844562 | I12: -0.69554387 | J12: 0.0073901934 | K12: 0.6955214 | L12: -0.71848286 | M12: -0.0056894167 | N12: 0.0092669662 | O12: 0.0010525012 | P12: 0.99995651 | Q12: -11.087378 | R12: -0.8736621 | S12: 0.60204628
A13: ETH-Trees | B13: fresh_control | C13: svd+ransac | D13: 12 | E13: s1 | F13: s2 | G13: 1 | H13: -0.71844562 | I13: -0.69554387 | J13: 0.0073901934 | K13: 0.6955214 | L13: -0.71848286 | M13: -0.0056894167 | N13: 0.0092669662 | O13: 0.0010525012 | P13: 0.99995651 | Q13: -11.087378 | R13: -0.8736621 | S13: 0.60204628
... A29: ETH-Trees | B29: fresh_control | C29: svd+ransac | D29: 13 | E29: s1 | F29: s5 | G29: 1 | H29: 0.22739118 | I29: -0.97380156 | J29: 0.0019401214 | K29: 0.97375896 | L29: 0.22736127 | M29: -0.010017202 | N29: 0.0093136583 | O29: 0.004167034 | P29: 0.99994794 | Q29: -16.503814 | R29: 20.549695 | S29: 1.1078242
A30: ETH-Trees | B30: fresh_control | C30: svd | D30: 13 | E30: s1 | F30: s6 | G30: 0
A31: ETH-Trees | B31: fresh_control | C31: svd+ransac | D31: 13 | E31: s1 | F31: s6 | G31: 0
A32: ETH-Trees | B32: fresh_control | C32: svd | D32: 14 | E32: s1 | F32: s2 | G32: 0
A33: ETH-Trees | B33: fresh_control | C33: svd+ransac | D33: 14 | E33: s1 | F33: s2 | G33: 0
A34: ETH-Trees | B34: fresh_control | C34: svd | D34: 14 | E34: s1 | F34: s3 | G34: 1 | H34: 0.93339472 | I34: 0.35860254 | J34: -0.013360767 | K34: -0.35846026 | L34: 0.93346879 | M34: 0.011927343 | N34: 0.016749034 | O34: -0.0063436155 | P34: 0.9998396 | Q34: 8.3745377 | R34: 1.381641 | S34: 0.78869758
A35: ETH-Trees | B35: fresh_control | C35: svd+ransac | D35: 14 | E35: s1 | F35: s3 | G35: 1 | H35: 0.93339472 | I35: 0.35860254 | J35: -0.013360767 | K35: -0.35846026 | L35: 0.93346879 | M35: 0.011927343 | N35: 0.016749034 | O35: -0.0063436155 | P35: 0.9998396 | Q35: 8.3745377 | R35: 1.381641 | S35: 0.78869758
A36: ETH-Trees | B36: fresh_control | C36: svd | D36: 14 | E36: s1 | F36: s4 | G36: 0
A37: ETH-Trees | B37: fresh_control | C37: svd+ransac | D37: 14 | E37: s1 | F37: s4 | G37: 0
A38: ETH-Trees | B38: fresh_control | C38: svd | D38: 14 | E38: s1 | F38: s5 | G38: 1 | H38: 0.22629018 | I38: -0.9739546 | J38: 0.014324869 | K38: 0.97404968 | L38: 0.22619584 | M38: -0.0079158845 | N38: 0.0044694862 | O38: 0.015744421 | P38: 0.99986606 | Q38: -16.492219 | R38: 20.502457 | S38: 1.232499
A39: ETH-Trees | B39: fresh_control | C39: svd+ransac | D39: 14 | E39: s1 | F39: s5 | G39: 1 | H39: 0.22629018 | I39: -0.9739546 | J39: 0.014324869 | K39: 0.97404968 | L39: 0.22619584 | M39: -0.0079158845 | N39: 0.0044694862 | O39: 0.015744421 | P39: 0.99986606 | Q39: -16.492219 | R39: 20.502457 | S39: 1.232499
A40: ETH-Trees | B40: fresh_control | C40: svd | D40: 14 | E40: s1 | F40: s6 | G40: 1 | H40: 0.98690711 | I40: 0.15330573 | J40: -0.050116909 | K40: -0.15113655 | L40: 0.98750828 | M40: 0.04455482 | N40: 0.056321372 | O40: -0.036396972 | P40: 0.99774905 | Q40: 25.088068 | R40: 19.888485 | S40: 2.2753003
A41: ETH-Trees | B41: fresh_control | C41: svd+ransac | D41: 14 | E41: s1 | F41: s6 | G41: 1 | H41: 0.98815176 | I41: 0.15240517 | J41: -0.018132019 | K41: -0.15197385 | L41: 0.98811271 | M41: 0.023178002 | N41: 0.021448926 | O41: -0.020147791 | P41: 0.99956691 | Q41: 25.150246 | R41: 19.858751 | S41: 2.2178402
A42: ETH-Trees | B42: fresh_control | C42: svd | D42: 15 | E42: s1 | F42: s2 | G42: 1 | H42: -0.71628813 | I42: -0.69780353 | J42: -0.0012454805 | K42: 0.69778182 | L42: -0.71624913 | M42: -0.0093656958 | N42: 0.0056433413 | O42: -0.0075776104 | P42: 0.99995537 | Q42: -11.101492 | R42: -0.81372992 | S42: 0.45029086
A43: ETH-Trees | B43: fresh_control | C43: svd+ransac | D43: 15 | E43: s1 | F43: s2 | G43: 1 | H43: -0.71628813 | I43: -0.69780353 | J43: -0.0012454805 | K43: 0.69778182 | L43: -0.71624913 | M43: -0.0093656958 | N43: 0.0056433413 | O43: -0.0075776104 | P43: 0.99995537 | Q43: -11.101492 | R43: -0.81372992 | S43: 0.45029086
A44: ETH-Trees | B44: fresh_control | C44: svd | D44: 15 | E44: s1 | F44: s3 | G44: 1 | H44: 0.93455653 | I44: 0.35578446 | J44: -0.0046374427 | K44: -0.35578598 | L44: 0.93456731 | M44: 0.00052059559 | N44: 0.0045192222 | O44: 0.0011634111 | P44: 0.99998911 | Q44: 8.3914071 | R44: 1.3878388 | S44: 0.68365974
A45: ETH-Trees | B45: fresh_control | C45: svd+ransac | D45: 15 | E45: s1 | F45: s3 | G45: 1 | H45: 0.93455653 | I45: 0.35578446 | J45: -0.0046374427 | K45: -0.35578598 | L45: 0.93456731 | M45: 0.00052059559 | N45: 0.0045192222 | O45: 0.0011634111 | P45: 0.99998911 | Q45: 8.3914071 | R45: 1.3878388 | S45: 0.68365974
A46: ETH-Trees | B46: fresh_control | C46: svd | D46: 15 | E46: s1 | F46: s4 | G46: 0
A47: ETH-Trees | B47: fresh_control | C47: svd+ransac | D47: 15 | E47: s1 | F47: s4 | G47: 0
A48: ETH-Trees | B48: fresh_control | C48: svd | D48: 15 | E48: s1 | F48: s5 | G48: 1 | H48: 0.22299296 | I48: -0.97478682 | J48: 0.0080494698 | K48: 0.97474142 | L48: 0.22286249 | M48: -0.014542197 | N48: 0.012381617 | O48: 0.011088959 | P48: 0.99986186 | Q48: -16.563046 | R48: 20.463895 | S48: 1.2989194
A49: ETH-Trees | B49: fresh_control | C49: svd+ransac | D49: 15 | E49: s1 | F49: s5 | G49: 1 | H49: 0.22299296 | I49: -0.97478682 | J49: 0.0080494698 | K49: 0.97474142 | L49: 0.22286249 | M49: -0.014542197 | N49: 0.012381617 | O49: 0.011088959 | P49: 0.99986186 | Q49: -16.563046 | R49: 20.463895 | S49: 1.2989194
A50: ETH-Trees | B50: fresh_control | C50: svd | D50: 15 | E50: s1 | F50: s6 | G50: 1 | H50: 0.98880565 | I50: 0.1478958 | J50: -0.019753873 | K50: -0.14771633 | L50: 0.98897652 | M50: 0.01026311 | N50: 0.021053987 | O50: -0.0072302518 | P50: 0.9997522 | Q50: 25.13007 | R50: 19.822542 | S50: 2.1739949
A51: ETH-Trees | B51: fresh_control | C51: svd+ransac | D51: 15 | E51: s1 | F51: s6 | G51: 1 | H51: 0.98880565 | I51: 0.1478958 | J51: -0.019753873 | K51: -0.14771633 | L51: 0.98897652 | M51: 0.01026311 | N51: 0.021053987 | O51: -0.0072302518 | P51: 0.9997522 | Q51: 25.13007 | R51: 19.822542 | S51: 2.1739949
A52: ETH-Trees | B52: fresh_control | C52: svd | D52: 16 | E52: s1 | F52: s2 | G52: 1 | H52: -0.7181442 | I52: -0.6958688 | J52: 0.0059595791 | K52: 0.69584682 | L52: -0.71816891 | M52: -0.0055340312 | N52: 0.0081309441 | O52: 0.00017272177 | P52: 0.99996693 | Q52: -11.073243 | R52: -0.87428087 | S52: 0.59690736
A53: ETH-Trees | B53: fresh_control | C53: svd+ransac | D53: 16 | E53: s1 | F53: s2 | G53: 1 | H53: -0.7181442 | I53: -0.6958688 | J53: 0.0059595791 | K53: 0.69584682 | L53: -0.71816891 | M53: -0.0055340312 | N53: 0.0081309441 | O53: 0.00017272177 | P53: 0.99996693 | Q53: -11.073243 | R53: -0.87428087 | S53: 0.59690736
A54: ETH-Trees | B54: fresh_control | C54: svd | D54: 16 | E54: s1 | F54: s3 | G54: 1 | H54: 0.93424634 | I54: 0.35651402 | J54: -0.0090296834 | K54: -0.35647507 | L54: 0.93428768 | M54: 0.0056623033 | N54: 0.010455012 | O54: -0.0020711291 | P54: 0.9999432 | Q54: 8.3886131 | R54: 1.3959354 | S54: 0.70248018
A55: ETH-Trees | B55: fresh_control | C55: svd+ransac | D55: 16 | E55: s1 | F55: s3 | G55: 1 | H55: 0.93424634 | I55: 0.35651402 | J55: -0.0090296834 | K55: -0.35647507 | L55: 0.93428768 | M55: 0.0056623033 | N55: 0.010455012 | O55: -0.0020711291 | P55: 0.9999432 | Q55: 8.3886131 | R55: 1.3959354 | S55: 0.70248018
...

Sheet 資料集摘要
A1: 資料集 | B1: 任務 | C1: 方法代碼 | D1: solver | E1: 案例數 | F1: 成功數 | G1: 成功率 | H1: 官方案例數 | I1: 官方成功數 | J1: 官方成功率 | K1: 成功e_p中位數m | L1: 每seed成功對數SD | M1: 狀態 | N1: 匹配＋求解ms中位數
A2: ETH-Trees | B2: 兩站 | C2: fresh_control | D2: svd | E2: =COUNTIFS(逐對結果!$A$2:$A$1951,$A2,逐對結果!$D$2:$D$1951,$C2,逐對結果!$E$2:$E$1951,$D2) -> 150 | F2: =COUNTIFS(逐對結果!$A$2:$A$1951,$A2,逐對結果!$D$2:$D$1951,$C2,逐對結果!$E$2:$E$1951,$D2,逐對結果!$J$2:$J$1951,1) -> 118 | G2: =IF(E2=0,"",F2/E2) -> 0.78666667 | H2: =COUNTIFS(逐對結果!$A$2:$A$1951,$A2,逐對結果!$D$2:$D$1951,$C2,逐對結果!$E$2:$E$1951,$D2,逐對結果!$H$2:$H$1951,1) -> 100 | I2: =COUNTIFS(逐對結果!$A$2:$A$1951,$A2,逐對結果!$D$2:$D$1951,$C2,逐對結果!$E$2:$E$1951,$D2,逐對結果!$H$2:$H$1951,1,逐對結果!$J$2:$J$1951,1) -> 88 | J2: =IF(H2=0,"",I2/H2) -> 0.88 | K2: 0.070338766 | L2: 1.6193277 | M2: 完成 | N2: 2.5001855
A3: ETH-Trees | B3: 兩站 | C3: fresh_control | D3: svd+ransac | E3: =COUNTIFS(逐對結果!$A$2:$A$1951,$A3,逐對結果!$D$2:$D$1951,$C3,逐對結果!$E$2:$E$1951,$D3) -> 150 | F3: =COUNTIFS(逐對結果!$A$2:$A$1951,$A3,逐對結果!$D$2:$D$1951,$C3,逐對結果!$E$2:$E$1951,$D3,逐對結果!$J$2:$J$1951,1) -> 123 | G3: =IF(E3=0,"",F3/E3) -> 0.82 | H3: =COUNTIFS(逐對結果!$A$2:$A$1951,$A3,逐對結果!$D$2:$D$1951,$C3,逐對結果!$E$2:$E$1951,$D3,逐對結果!$H$2:$H$1951,1) -> 100 | I3: =COUNTIFS(逐對結果!$A$2:$A$1951,$A3,逐對結果!$D$2:$D$1951,$C3,逐對結果!$E$2:$E$1951,$D3,逐對結果!$H$2:$H$1951,1,逐對結果!$J$2:$J$1951,1) -> 90 | J3: =IF(H3=0,"",I3/H3) -> 0.9 | K3: 0.072596099 | L3: 1.4944341 | M3: 完成 | N3: 3.641594
A4: ETH-Trees | B4: 兩站 | C4: fresh_matching | D4: svd | E4: =COUNTIFS(逐對結果!$A$2:$A$1951,$A4,逐對結果!$D$2:$D$1951,$C4,逐對結果!$E$2:$E$1951,$D4) -> 150 | F4: =COUNTIFS(逐對結果!$A$2:$A$1951,$A4,逐對結果!$D$2:$D$1951,$C4,逐對結果!$E$2:$E$1951,$D4,逐對結果!$J$2:$J$1951,1) -> 135 | G4: =IF(E4=0,"",F4/E4) -> 0.9 | H4: =COUNTIFS(逐對結果!$A$2:$A$1951,$A4,逐對結果!$D$2:$D$1951,$C4,逐對結果!$E$2:$E$1951,$D4,逐對結果!$H$2:$H$1951,1) -> 100 | I4: =COUNTIFS(逐對結果!$A$2:$A$1951,$A4,逐對結果!$D$2:$D$1951,$C4,逐對結果!$E$2:$E$1951,$D4,逐對結果!$H$2:$H$1951,1,逐對結果!$J$2:$J$1951,1) -> 97 | J4: =IF(H4=0,"",I4/H4) -> 0.97 | K4: 0.078827995 | L4: 1.2692955 | M4: 完成 | N4: 3.153391
A5: ETH-Trees | B5: 兩站 | C5: fresh_matching | D5: svd+ransac | E5: =COUNTIFS(逐對結果!$A$2:$A$1951,$A5,逐對結果!$D$2:$D$1951,$C5,逐對結果!$E$2:$E$1951,$D5) -> 150 | F5: =COUNTIFS(逐對結果!$A$2:$A$1951,$A5,逐對結果!$D$2:$D$1951,$C5,逐對結果!$E$2:$E$1951,$D5,逐對結果!$J$2:$J$1951,1) -> 142 | G5: =IF(E5=0,"",F5/E5) -> 0.94666667 | H5: =COUNTIFS(逐對結果!$A$2:$A$1951,$A5,逐對結果!$D$2:$D$1951,$C5,逐對結果!$E$2:$E$1951,$D5,逐對結果!$H$2:$H$1951,1) -> 100 | I5: =COUNTIFS(逐對結果!$A$2:$A$1951,$A5,逐對結果!$D$2:$D$1951,$C5,逐對結果!$E$2:$E$1951,$D5,逐對結果!$H$2:$H$1951,1,逐對結果!$J$2:$J$1951,1) -> 99 | J5: =IF(H5=0,"",I5/H5) -> 0.99 | K5: 0.070235819 | L5: 0.63245553 | M5: 完成 | N5: 6.11513
A6: ETH-Trees | B6: 兩站 | C6: fresh_vertical085 | D6: svd | E6: =COUNTIFS(逐對結果!$A$2:$A$1951,$A6,逐對結果!$D$2:$D$1951,$C6,逐對結果!$E$2:$E$1951,$D6) -> 150 | F6: =COUNTIFS(逐對結果!$A$2:$A$1951,$A6,逐對結果!$D$2:$D$1951,$C6,逐對結果!$E$2:$E$1951,$D6,逐對結果!$J$2:$J$1951,1) -> 113 | G6: =IF(E6=0,"",F6/E6) -> 0.75333333 | H6: =COUNTIFS(逐對結果!$A$2:$A$1951,$A6,逐對結果!$D$2:$D$1951,$C6,逐對結果!$E$2:$E$1951,$D6,逐對結果!$H$2:$H$1951,1) -> 100 | I6: =COUNTIFS(逐對結果!$A$2:$A$1951,$A6,逐對結果!$D$2:$D$1951,$C6,逐對結果!$E$2:$E$1951,$D6,逐對結果!$H$2:$H$1951,1,逐對結果!$J$2:$J$1951,1) -> 86 | J6: =IF(H6=0,"",I6/H6) -> 0.86 | K6: 0.081795176 | L6: 1.8287822 | M6: 完成 | N6: 2.3491565
A7: ETH-Trees | B7: 兩站 | C7: fresh_vertical085 | D7: svd+ransac | E7: =COUNTIFS(逐對結果!$A$2:$A$1951,$A7,逐對結果!$D$2:$D$1951,$C7,逐對結果!$E$2:$E$1951,$D7) -> 150 | F7: =COUNTIFS(逐對結果!$A$2:$A$1951,$A7,逐對結果!$D$2:$D$1951,$C7,逐對結果!$E$2:$E$1951,$D7,逐對結果!$J$2:$J$1951,1) -> 115 | G7: =IF(E7=0,"",F7/E7) -> 0.76666667 | H7: =COUNTIFS(逐對結果!$A$2:$A$1951,$A7,逐對結果!$D$2:$D$1951,$C7,逐對結果!$E$2:$E$1951,$D7,逐對結果!$H$2:$H$1951,1) -> 100 | I7: =COUNTIFS(逐對結果!$A$2:$A$1951,$A7,逐對結果!$D$2:$D$1951,$C7,逐對結果!$E$2:$E$1951,$D7,逐對結果!$H$2:$H$1951,1,逐對結果!$J$2:$J$1951,1) -> 88 | J7: =IF(H7=0,"",I7/H7) -> 0.88 | K7: 0.077414101 | L7: 1.8408935 | M7: 完成 | N7: 2.569853
A8: ETH-Trees | B8: 兩站 | C8: fresh_vertical085_matching | D8: svd | E8: =COUNTIFS(逐對結果!$A$2:$A$1951,$A8,逐對結果!$D$2:$D$1951,$C8,逐對結果!$E$2:$E$1951,$D8) -> 150 | F8: =COUNTIFS(逐對結果!$A$2:$A$1951,$A8,逐對結果!$D$2:$D$1951,$C8,逐對結果!$E$2:$E$1951,$D8,逐對結果!$J$2:$J$1951,1) -> 131 | G8: =IF(E8=0,"",F8/E8) -> 0.87333333 | H8: =COUNTIFS(逐對結果!$A$2:$A$1951,$A8,逐對結果!$D$2:$D$1951,$C8,逐對結果!$E$2:$E$1951,$D8,逐對結果!$H$2:$H$1951,1) -> 100 | I8: =COUNTIFS(逐對結果!$A$2:$A$1951,$A8,逐對結果!$D$2:$D$1951,$C8,逐對結果!$E$2:$E$1951,$D8,逐對結果!$H$2:$H$1951,1,逐對結果!$J$2:$J$1951,1) -> 96 | J8: =IF(H8=0,"",I8/H8) -> 0.96 | K8: 0.071792605 | L8: 0.99442893 | M8: 完成 | N8: 2.4882075
A9: ETH-Trees | B9: 兩站 | C9: fresh_vertical085_matching | D9: svd+ransac | E9: =COUNTIFS(逐對結果!$A$2:$A$1951,$A9,逐對結果!$D$2:$D$1951,$C9,逐對結果!$E$2:$E$1951,$D9) -> 150 | F9: =COUNTIFS(逐對結果!$A$2:$A$1951,$A9,逐對結果!$D$2:$D$1951,$C9,逐對結果!$E$2:$E$1951,$D9,逐對結果!$J$2:$J$1951,1) -> 130 | G9: =IF(E9=0,"",F9/E9) -> 0.86666667 | H9: =COUNTIFS(逐對結果!$A$2:$A$1951,$A9,逐對結果!$D$2:$D$1951,$C9,逐對結果!$E$2:$E$1951,$D9,逐對結果!$H$2:$H$1951,1) -> 100 | I9: =COUNTIFS(逐對結果!$A$2:$A$1951,$A9,逐對結果!$D$2:$D$1951,$C9,逐對結果!$E$2:$E$1951,$D9,逐對結果!$H$2:$H$1951,1,逐對結果!$J$2:$J$1951,1) -> 95 | J9: =IF(H9=0,"",I9/H9) -> 0.95 | K9: 0.065574284 | L9: 0.94280904 | M9: 完成 | N9: 2.896751
A10: ETH-Trees | B10: 兩站 | C10: fresh_ransac999 | D10: svd | E10: =COUNTIFS(逐對結果!$A$2:$A$1951,$A10,逐對結果!$D$2:$D$1951,$C10,逐對結果!$E$2:$E$1951,$D10) -> 150 | F10: =COUNTIFS(逐對結果!$A$2:$A$1951,$A10,逐對結果!$D$2:$D$1951,$C10,逐對結果!$E$2:$E$1951,$D10,逐對結果!$J$2:$J$1951,1) -> 117 | G10: =IF(E10=0,"",F10/E10) -> 0.78 | H10: =COUNTIFS(逐對結果!$A$2:$A$1951,$A10,逐對結果!$D$2:$D$1951,$C10,逐對結果!$E$2:$E$1951,$D10,逐對結果!$H$2:$H$1951,1) -> 100 | I10: =COUNTIFS(逐對結果!$A$2:$A$1951,$A10,逐對結果!$D$2:$D$1951,$C10,逐對結果!$E$2:$E$1951,$D10,逐對結果!$H$2:$H$1951,1,逐對結果!$J$2:$J$1951,1) -> 89 | J10: =IF(H10=0,"",I10/H10) -> 0.89 | K10: 0.074326748 | L10: 1.2516656 | M10: 完成 | N10: 2.1896205
A11: ETH-Trees | B11: 兩站 | C11: fresh_ransac999 | D11: svd+ransac | E11: =COUNTIFS(逐對結果!$A$2:$A$1951,$A11,逐對結果!$D$2:$D$1951,$C11,逐對結果!$E$2:$E$1951,$D11) -> 150 | F11: =COUNTIFS(逐對結果!$A$2:$A$1951,$A11,逐對結果!$D$2:$D$1951,$C11,逐對結果!$E$2:$E$1951,$D11,逐對結果!$J$2:$J$1951,1) -> 122 | G11: =IF(E11=0,"",F11/E11) -> 0.81333333 | H11: =COUNTIFS(逐對結果!$A$2:$A$1951,$A11,逐對結果!$D$2:$D$1951,$C11,逐對結果!$E$2:$E$1951,$D11,逐對結果!$H$2:$H$1951,1) -> 100 | I11: =COUNTIFS(逐對結果!$A$2:$A$1951,$A11,逐對結果!$D$2:$D$1951,$C11,逐對結果!$E$2:$E$1951,$D11,逐對結果!$H$2:$H$1951,1,逐對結果!$J$2:$J$1951,1) -> 93 | J11: =IF(H11=0,"",I11/H11) -> 0.93 | K11: 0.075780952 | L11: 0.91893658 | M11: 完成 | N11: 2.424939
A12: ETH-Trees | B12: 兩站 | C12: fresh_ransac999_matching | D12: svd | E12: =COUNTIFS(逐對結果!$A$2:$A$1951,$A12,逐對結果!$D$2:$D$1951,$C12,逐對結果!$E$2:$E$1951,$D12) -> 150 | F12: =COUNTIFS(逐對結果!$A$2:$A$1951,$A12,逐對結果!$D$2:$D$1951,$C12,逐對結果!$E$2:$E$1951,$D12,逐對結果!$J$2:$J$1951,1) -> 138 | G12: =IF(E12=0,"",F12/E12) -> 0.92 | H12: =COUNTIFS(逐對結果!$A$2:$A$1951,$A12,逐對結果!$D$2:$D$1951,$C12,逐對結果!$E$2:$E$1951,$D12,逐對結果!$H$2:$H$1951,1) -> 100 | I12: =COUNTIFS(逐對結果!$A$2:$A$1951,$A12,逐對結果!$D$2:$D$1951,$C12,逐對結果!$E$2:$E$1951,$D12,逐對結果!$H$2:$H$1951,1,逐對結果!$J$2:$J$1951,1) -> 97 | J12: =IF(H12=0,"",I12/H12) -> 0.97 | K12: 0.074911237 | L12: 0.78881064 | M12: 完成 | N12: 2.346764
A13: ETH-Trees | B13: 兩站 | C13: fresh_ransac999_matching | D13: svd+ransac | E13: =COUNTIFS(逐對結果!$A$2:$A$1951,$A13,逐對結果!$D$2:$D$1951,$C13,逐對結果!$E$2:$E$1951,$D13) -> 150 | F13: =COUNTIFS(逐對結果!$A$2:$A$1951,$A13,逐對結果!$D$2:$D$1951,$C13,逐對結果!$E$2:$E$1951,$D13,逐對結果!$J$2:$J$1951,1) -> 141 | G13: =IF(E13=0,"",F13/E13) -> 0.94 | H13: =COUNTIFS(逐對結果!$A$2:$A$1951,$A13,逐對結果!$D$2:$D$1951,$C13,逐對結果!$E$2:$E$1951,$D13,逐對結果!$H$2:$H$1951,1) -> 100 | I13: =COUNTIFS(逐對結果!$A$2:$A$1951,$A13,逐對結果!$D$2:$D$1951,$C13,逐對結果!$E$2:$E$1951,$D13,逐對結果!$H$2:$H$1951,1,逐對結果!$J$2:$J$1951,1) -> 98 | J13: =IF(H13=0,"",I13/H13) -> 0.98 | K13: 0.068199223 | L13: 0.56764621 | M13: 完成 | N13: 2.775542
A14: ETH-Trees | B14: 多站 | C14: graph_mst | D14: graph_mst | E14: =COUNTIFS(逐對結果!$A$2:$A$1951,$A14,逐對結果!$D$2:$D$1951,$C14,逐對結果!$E$2:$E$1951,$D14) -> 150 | F14: =COUNTIFS(逐對結果!$A$2:$A$1951,$A14,逐對結果!$D$2:$D$1951,$C14,逐對結果!$E$2:$E$1951,$D14,逐對結果!$J$2:$J$1951,1) -> 150 | G14: =IF(E14=0,"",F14/E14) -> 1 | H14: =COUNTIFS(逐對結果!$A$2:$A$1951,$A14,逐對結果!$D$2:$D$1951,$C14,逐對結果!$E$2:$E$1951,$D14,逐對結果!$H$2:$H$1951,1) -> 100 | I14: =COUNTIFS(逐對結果!$A$2:$A$1951,$A14,逐對結果!$D$2:$D$1951,$C14,逐對結果!$E$2:$E$1951,$D14,逐對結果!$H$2:$H$1951,1,逐對結果!$J$2:$J$1951,1) -> 100 | J14: =IF(H14=0,"",I14/H14) -> 1 | K14: 0.071879095 | L14: 0 | M14: 完成

Sheet 每seed
A1: 資料集 | B1: 方法代碼 | C1: solver | D1: seed | E1: 案例數 | F1: 成功數 | G1: 成功率
A2: ETH-Trees | B2: fresh_control | C2: svd | D2: 11 | E2: 15 | F2: 11 | G2: 0.73333333
A3: ETH-Trees | B3: fresh_control | C3: svd | D3: 12 | E3: 15 | F3: 13 | G3: 0.86666667
A4: ETH-Trees | B4: fresh_control | C4: svd | D4: 13 | E4: 15 | F4: 10 | G4: 0.66666667
A5: ETH-Trees | B5: fresh_control | C5: svd | D5: 14 | E5: 15 | F5: 9 | G5: 0.6
A6: ETH-Trees | B6: fresh_control | C6: svd | D6: 15 | E6: 15 | F6: 14 | G6: 0.93333333
A7: ETH-Trees | B7: fresh_control | C7: svd | D7: 16 | E7: 15 | F7: 13 | G7: 0.86666667
A8: ETH-Trees | B8: fresh_control | C8: svd | D8: 17 | E8: 15 | F8: 11 | G8: 0.73333333
A9: ETH-Trees | B9: fresh_control | C9: svd | D9: 18 | E9: 15 | F9: 13 | G9: 0.86666667
A10: ETH-Trees | B10: fresh_control | C10: svd | D10: 19 | E10: 15 | F10: 13 | G10: 0.86666667
A11: ETH-Trees | B11: fresh_control | C11: svd | D11: 20 | E11: 15 | F11: 11 | G11: 0.73333333
A12: ETH-Trees | B12: fresh_control | C12: svd+ransac | D12: 11 | E12: 15 | F12: 13 | G12: 0.86666667
A13: ETH-Trees | B13: fresh_control | C13: svd+ransac | D13: 12 | E13: 15 | F13: 13 | G13: 0.86666667
... A131: ETH-Trees | B131: graph_mst | C131: graph_mst | D131: 20 | E131: 15 | F131: 15 | G131: 1

Sheet 配對比較
A1: 資料集 | B1: 方法代碼 | C1: solver | D1: Δ成功對數/seed | E1: 勝seed數 | F1: 負seed數 | G1: 相同seed數 | H1: 符號檢定p | I1: Bonferroni p | J1: 共同成功案例 | K1: control共同成功e_p | L1: 此方法共同成功e_p
A2: ETH-Trees | B2: fresh_control | C2: svd | D2: 0 | E2: 0 | F2: 0 | G2: 10 | H2: 1 | I2: 1 | J2: 118 | K2: 0.070338766 | L2: 0.070338766
A3: ETH-Trees | B3: fresh_control | C3: svd+ransac | D3: 0.5 | E3: 4 | F3: 0 | G3: 6 | H3: 0.125 | I3: 1 | J3: 118 | K3: 0.070338766 | L3: 0.071269044
A4: ETH-Trees | B4: fresh_matching | C4: svd | D4: 1.7 | E4: 8 | F4: 0 | G4: 2 | H4: 0.0078125 | I4: 0.09375 | J4: 110 | K4: 0.069631568 | L4: 0.072455075
A5: ETH-Trees | B5: fresh_matching | C5: svd+ransac | D5: 2.4 | E5: 9 | F5: 0 | G5: 1 | H5: 0.00390625 | I5: 0.046875 | J5: 111 | K5: 0.069868137 | L5: 0.066134851
A6: ETH-Trees | B6: fresh_vertical085 | C6: svd | D6: -0.5 | E6: 3 | F6: 5 | G6: 2 | H6: 0.7265625 | I6: 1 | J6: 90 | K6: 0.069162467 | L6: 0.077996585
A7: ETH-Trees | B7: fresh_vertical085 | C7: svd+ransac | D7: -0.3 | E7: 4 | F7: 6 | G7: 0 | H7: 0.75390625 | I7: 1 | J7: 92 | K7: 0.068575644 | L7: 0.071791949
A8: ETH-Trees | B8: fresh_vertical085_matching | C8: svd | D8: 1.3 | E8: 7 | F8: 3 | G8: 0 | H8: 0.34375 | I8: 1 | J8: 104 | K8: 0.070338766 | L8: 0.071813528
A9: ETH-Trees | B9: fresh_vertical085_matching | C9: svd+ransac | D9: 1.2 | E9: 7 | F9: 2 | G9: 1 | H9: 0.1796875 | I9: 1 | J9: 103 | K9: 0.069395 | L9: 0.062918354
A10: ETH-Trees | B10: fresh_ransac999 | C10: svd | D10: -0.1 | E10: 5 | F10: 4 | G10: 1 | H10: 1 | I10: 1 | J10: 101 | K10: 0.069868137 | L10: 0.074326748
A11: ETH-Trees | B11: fresh_ransac999 | C11: svd+ransac | D11: 0.4 | E11: 6 | F11: 4 | G11: 0 | H11: 0.75390625 | I11: 1 | J11: 104 | K11: 0.070338766 | L11: 0.075780952
A12: ETH-Trees | B12: fresh_ransac999_matching | C12: svd | D12: 2 | E12: 10 | F12: 0 | G12: 0 | H12: 0.001953125 | I12: 0.0234375 | J12: 114 | K12: 0.069919953 | L12: 0.071780792
A13: ETH-Trees | B13: fresh_ransac999_matching | C13: svd+ransac | D13: 2.3 | E13: 10 | F13: 0 | G13: 0 | H13: 0.001953125 | I13: 0.0234375 | J13: 114 | K13: 0.069919953 | L13: 0.066048721
A14: ETH-Trees | B14: graph_mst | C14: graph_mst | D14: 3.2 | E14: 10 | F14: 0 | G14: 0 | H14: 0.001953125 | I14: 0.0234375 | J14: 118 | K14: 0.070338766 | L14: 0.069649254

Sheet 跨資料集
A1: 任務 | B1: 方法代碼 | C1: solver | D1: ETH-Trees | E1: Tongji-Trees | F1: WHU-FGI | G1: Liang2018
A2: 兩站 | B2: fresh_control | C2: svd | D2: =資料集摘要!G2 -> 0.78666667 | E2: 未執行／待取得資料 | F2: 未執行／待取得資料 | G2: 未執行／待取得資料
A3: 兩站 | B3: fresh_control | C3: svd+ransac | D3: =資料集摘要!G3 -> 0.82 | E3: 未執行／待取得資料 | F3: 未執行／待取得資料 | G3: 未執行／待取得資料
A4: 兩站 | B4: fresh_matching | C4: svd | D4: =資料集摘要!G4 -> 0.9 | E4: 未執行／待取得資料 | F4: 未執行／待取得資料 | G4: 未執行／待取得資料
A5: 兩站 | B5: fresh_matching | C5: svd+ransac | D5: =資料集摘要!G5 -> 0.94666667 | E5: 未執行／待取得資料 | F5: 未執行／待取得資料 | G5: 未執行／待取得資料
A6: 兩站 | B6: fresh_vertical085 | C6: svd | D6: =資料集摘要!G6 -> 0.75333333 | E6: 未執行／待取得資料 | F6: 未執行／待取得資料 | G6: 未執行／待取得資料
A7: 兩站 | B7: fresh_vertical085 | C7: svd+ransac | D7: =資料集摘要!G7 -> 0.76666667 | E7: 未執行／待取得資料 | F7: 未執行／待取得資料 | G7: 未執行／待取得資料
A8: 兩站 | B8: fresh_vertical085_matching | C8: svd | D8: =資料集摘要!G8 -> 0.87333333 | E8: 未執行／待取得資料 | F8: 未執行／待取得資料 | G8: 未執行／待取得資料
A9: 兩站 | B9: fresh_vertical085_matching | C9: svd+ransac | D9: =資料集摘要!G9 -> 0.86666667 | E9: 未執行／待取得資料 | F9: 未執行／待取得資料 | G9: 未執行／待取得資料
A10: 兩站 | B10: fresh_ransac999 | C10: svd | D10: =資料集摘要!G10 -> 0.78 | E10: 未執行／待取得資料 | F10: 未執行／待取得資料 | G10: 未執行／待取得資料
A11: 兩站 | B11: fresh_ransac999 | C11: svd+ransac | D11: =資料集摘要!G11 -> 0.81333333 | E11: 未執行／待取得資料 | F11: 未執行／待取得資料 | G11: 未執行／待取得資料
A12: 兩站 | B12: fresh_ransac999_matching | C12: svd | D12: =資料集摘要!G12 -> 0.92 | E12: 未執行／待取得資料 | F12: 未執行／待取得資料 | G12: 未執行／待取得資料
A13: 兩站 | B13: fresh_ransac999_matching | C13: svd+ransac | D13: =資料集摘要!G13 -> 0.94 | E13: 未執行／待取得資料 | F13: 未執行／待取得資料 | G13: 未執行／待取得資料
A14: 多站 | B14: graph_mst | C14: graph_mst | D14: =資料集摘要!G14 -> 1 | E14: 未執行／待取得資料 | F14: 未執行／待取得資料 | G14: 未執行／待取得資料

Sheet 方法設定
A1: 方法代碼 | B1: solver | C1: 任務 | D1: 匹配閾值m | E1: N | F1: w | G1: Th_score | H1: min_dc | I1: cluster m | J1: verticality | K1: 圓柱prob | L1: 圓柱迭代上限 | M1: 配準RANSAC inlier m | N1: 補充
A2: fresh_control | B2: svd | C2: 兩站 | D2: 0.05 | E2: 183 | F2: 10 | G2: 40 | H2: 3 | I2: 0.2 | J2: 0.9 | K2: 0.99 | L2: 1000 | N2: 完整6DOF；不做ICP
A3: fresh_control | B3: svd+ransac | C3: 兩站 | D3: 0.05 | E3: 183 | F3: 10 | G3: 40 | H3: 3 | I3: 0.2 | J3: 0.9 | K3: 0.99 | L3: 1000 | M3: 0.3 | N3: 完整6DOF；不做ICP
A4: fresh_matching | B4: svd | C4: 兩站 | D4: 0.1 | E4: 183 | F4: 10 | G4: 40 | H4: 3 | I4: 0.2 | J4: 0.9 | K4: 0.99 | L4: 1000 | N4: 完整6DOF；不做ICP
A5: fresh_matching | B5: svd+ransac | C5: 兩站 | D5: 0.1 | E5: 183 | F5: 10 | G5: 40 | H5: 3 | I5: 0.2 | J5: 0.9 | K5: 0.99 | L5: 1000 | M5: 0.3 | N5: 完整6DOF；不做ICP
A6: fresh_vertical085 | B6: svd | C6: 兩站 | D6: 0.05 | E6: 183 | F6: 10 | G6: 40 | H6: 3 | I6: 0.2 | J6: 0.85 | K6: 0.99 | L6: 1000 | N6: 完整6DOF；不做ICP
A7: fresh_vertical085 | B7: svd+ransac | C7: 兩站 | D7: 0.05 | E7: 183 | F7: 10 | G7: 40 | H7: 3 | I7: 0.2 | J7: 0.85 | K7: 0.99 | L7: 1000 | M7: 0.3 | N7: 完整6DOF；不做ICP
A8: fresh_vertical085_matching | B8: svd | C8: 兩站 | D8: 0.1 | E8: 183 | F8: 10 | G8: 40 | H8: 3 | I8: 0.2 | J8: 0.85 | K8: 0.99 | L8: 1000 | N8: 完整6DOF；不做ICP
A9: fresh_vertical085_matching | B9: svd+ransac | C9: 兩站 | D9: 0.1 | E9: 183 | F9: 10 | G9: 40 | H9: 3 | I9: 0.2 | J9: 0.85 | K9: 0.99 | L9: 1000 | M9: 0.3 | N9: 完整6DOF；不做ICP
A10: fresh_ransac999 | B10: svd | C10: 兩站 | D10: 0.05 | E10: 183 | F10: 10 | G10: 40 | H10: 3 | I10: 0.2 | J10: 0.9 | K10: 0.999 | L10: 3000 | N10: 完整6DOF；不做ICP
A11: fresh_ransac999 | B11: svd+ransac | C11: 兩站 | D11: 0.05 | E11: 183 | F11: 10 | G11: 40 | H11: 3 | I11: 0.2 | J11: 0.9 | K11: 0.999 | L11: 3000 | M11: 0.3 | N11: 完整6DOF；不做ICP
A12: fresh_ransac999_matching | B12: svd | C12: 兩站 | D12: 0.1 | E12: 183 | F12: 10 | G12: 40 | H12: 3 | I12: 0.2 | J12: 0.9 | K12: 0.999 | L12: 3000 | N12: 完整6DOF；不做ICP
A13: fresh_ransac999_matching | B13: svd+ransac | C13: 兩站 | D13: 0.1 | E13: 183 | F13: 10 | G13: 40 | H13: 3 | I13: 0.2 | J13: 0.9 | K13: 0.999 | L13: 3000 | M13: 0.3 | N13: 完整6DOF；不做ICP
A14: graph_mst | B14: graph_mst | C14: 多站 | D14: 0.05 | E14: 183 | F14: 10 | G14: 40 | H14: 3 | I14: 0.2 | J14: 0.9 | K14: 0.99 | L14: 1000 | N14: 至少4個CN配對、6個3D支持；互為最近鄰距離<0.30m，中位殘差<=0.15m；不讀GT選邊

Sheet 資料來源
A1: 資料集 | B1: 項目 | C1: 內容
A2: ETH-Trees | B2: 已可執行配準比較 | C2: =TRUE() -> TRUE
A3: ETH-Trees | B3: 狀態 | C3: 已完成
A4: ETH-Trees | B4: 場景／子集 | C4: Trees
A5: ETH-Trees | B5: 已核驗站數 | C5: 6
A6: ETH-Trees | B6: 已核驗點數 | C6: 121489966
A7: ETH-Trees | B7: 來源頁 | C7: https://ethz.ch/content/dam/ethz/special-interest/baug/igp/photogrammetry-remote-sensing-dam/documents/sourcecode-and-datasets/PascalTheiler/trees.zip
A8: ETH-Trees | B8: 本地核驗SHA256 | C8: ecb3f5e8791804341a3e7837c29f25789987c99fdf575aa3ebfbfd67d3acd37c
A9: ETH-Trees | B9: 引用 | C9: Theiler et al., ISPRS J. 109 (2015); CircularMatch [11]
A10: Tongji-Trees | B10: 已可執行配準比較 | C10: =FALSE() -> FALSE
A11: Tongji-Trees | B11: 狀態 | C11: 未執行：官方要求申請下載連結
A12: Tongji-Trees | B12: 場景／子集
A13: Tongji-Trees | B13: 來源頁 | C13: https://github.com/zexinyang/GlobalMatch
A14: Tongji-Trees | B14: 原始下載候選 | C14: https://forms.gle/c8BXMHYTqd1iULBv8
A15: Tongji-Trees | B15: 引用 | C15: Wang et al., GlobalMatch, ISPRS J. 197 (2023); CircularMatch [9]
A16: WHU-FGI | B16: 已可執行配準比較 | C16: =FALSE() -> FALSE
A17: WHU-FGI | B17: 狀態 | C17: 未執行：公開整理版已下載，但不含FGI-Forest
A18: WHU-FGI | B18: 場景／子集 | C18: FGI-Forest（待核驗）
A19: WHU-FGI | B19: 來源頁 | C19: https://github.com/WHU-USI3DV/WHU-TLS
A20: WHU-FGI | B20: 原始下載候選 | C20: https://drive.google.com/file/d/1QjlxIVMQPinNWt5LKhtaG9TTo2j3TGs_/view
A21: WHU-FGI | B21: 引用 | C21: Dong et al., ISPRS J. 163 (2020); CircularMatch [12]
A22: WHU-FGI | B22: 補充來源 | C22: https://github.com/HpWang-whu/YOHO#-dataset--pretrained-model
A23: WHU-FGI | B23: 注意 | C23: 已取得YOHO公開WHU-TLS.tar.gz，387437741 bytes，SHA256 33a7a29577faa631c2a3bec828f9552182dbcbfd0da67ce572c8c28df60caf0a；gzip CRC已驗證。內容只有Campus/Mountain/Park/RiverBank/Tunnel/UndergroundExcavation，未含FGI-Forest；不能用這些場景代替論文FGI。
A24: Liang2018 | B24: 已可執行配準比較 | C24: =FALSE() -> FALSE
A25: Liang2018 | B25: 已取得森林點雲 | C25: =TRUE() -> TRUE
A26: Liang2018 | B26: 外部提取驗證完成 | C26: =TRUE() -> TRUE
A27: Liang2018 | B27: 狀態 | C27: 固定參數提取驗證180次已完成；配準缺少分站與真值
A28: Liang2018 | B28: 場景／子集 | C28: TreeTool處理後六樣區；原始分站資料待取得
A29: Liang2018 | B29: 已核驗點數 | C29: 37777514
A30: Liang2018 | B30: 來源頁 | C30: https://laserscanning.fi/results-available-for-international-benchmarking-of-terrestrial-laser-scanning-methods/
A31: Liang2018 | B31: 原始下載候選 | C31: https://helsinkifi-my.sharepoint.com/:f:/g/personal/jpyorala_ad_helsinki_fi/EvL7Zbq8VOpCqWMViRlswsIB06GH3HyOAQ1rupwb3fOEXg?e=KdWmd7
A32: Liang2018 | B32: 已取得處理版下載 | C32: https://drive.google.com/drive/folders/1AhYd8pwCrTAJCV4OIc9MWot8tjNgIJSx
A33: Liang2018 | B33: 引用 | C33: Liang et al., ISPRS J. 144 (2018), DOI 10.1016/j.isprsjprs.2018.06.021; CircularMatch [13]
A34: Liang2018 | B34: 補充來源 | C34: https://github.com/porteratzo/TreeTool
A35: Liang2018 | B35: 注意 | C35: 已取得6份處理後PCD及6份LHD參考樹資料。此版本每樣區僅一份點雲，未附原始站點、姿態或配準真值；可做提取驗證，不能當作完整配準資料。原始作者SharePoint分享網頁403、公開API401。

Sheet ETH篩選
A1: 設定 | B1: solver | C1: seed1–5成功 | D1: seed1–5案例 | E1: seed6–10成功 | F1: seed6–10案例 | G1: 參數
A2: control | B2: svd | C2: 63 | D2: 75 | E2: 63 | F2: 75 | G2: {"name": "control", "threshold": 0.05}
A3: control | B3: svd+ransac | C3: 61 | D3: 75 | E3: 65 | F3: 75 | G3: {"name": "control", "threshold": 0.05}
A4: threshold075 | B4: svd | C4: 64 | D4: 75 | E4: 62 | F4: 75 | G4: {"name": "threshold075", "threshold": 0.075}
A5: threshold075 | B5: svd+ransac | C5: 67 | D5: 75 | E5: 65 | F5: 75 | G5: {"name": "threshold075", "threshold": 0.075}
A6: threshold100 | B6: svd | C6: 68 | D6: 75 | E6: 67 | F6: 75 | G6: {"name": "threshold100", "threshold": 0.1}
A7: threshold100 | B7: svd+ransac | C7: 70 | D7: 75 | E7: 69 | F7: 75 | G7: {"name": "threshold100", "threshold": 0.1}
A8: score20 | B8: svd | C8: 62 | D8: 75 | E8: 59 | F8: 75 | G8: {"name": "score20", "threshold": 0.05, "th_score": 20}
A9: score20 | B9: svd+ransac | C9: 63 | D9: 75 | E9: 63 | F9: 75 | G9: {"name": "score20", "threshold": 0.05, "th_score": 20}
A10: score60 | B10: svd | C10: 52 | D10: 75 | E10: 57 | F10: 75 | G10: {"name": "score60", "threshold": 0.05, "th_score": 60}
A11: score60 | B11: svd+ransac | C11: 50 | D11: 75 | E11: 57 | F11: 75 | G11: {"name": "score60", "threshold": 0.05, "th_score": 60}
A12: min_dc4 | B12: svd | C12: 62 | D12: 75 | E12: 64 | F12: 75 | G12: {"name": "min_dc4", "threshold": 0.05, "min_dc": 4}
A13: min_dc4 | B13: svd+ransac | C13: 60 | D13: 75 | E13: 65 | F13: 75 | G13: {"name": "min_dc4", "threshold": 0.05, "min_dc": 4}
... A19: merge030 | B19: svd+ransac | C19: 58 | D19: 75 | E19: 65 | F19: 75 | G19: {"name": "merge030", "threshold": 0.05, "merge_radius": 0.3}

Sheet ETH提取
A1: 設定 | B1: 站點 | C1: seed數 | D1: 平均樹數 | E1: 樹數SD | F1: 10seed批次壁鐘秒 | G1: 計時條件
A2: control | B2: s1 | C2: 10 | D2: 54.6 | E2: 1.8973666 | F2: 165.344 | G2: 共享前處理、同時有其他工作；非獨占主機效能基準
A3: control | B3: s2 | C3: 10 | D3: 58.7 | E3: 1.5670212 | F3: 175.509 | G3: 共享前處理、同時有其他工作；非獨占主機效能基準
A4: control | B4: s3 | C4: 10 | D4: 48.8 | E4: 2.2010099 | F4: 167.032 | G4: 共享前處理、同時有其他工作；非獨占主機效能基準
A5: control | B5: s4 | C5: 10 | D5: 55 | E5: 1.9436506 | F5: 163.289 | G5: 共享前處理、同時有其他工作；非獨占主機效能基準
A6: control | B6: s5 | C6: 10 | D6: 84.8 | E6: 4.5655716 | F6: 191.872 | G6: 共享前處理、同時有其他工作；非獨占主機效能基準
A7: control | B7: s6 | C7: 10 | D7: 86.5 | E7: 3.7785947 | F7: 195.476 | G7: 共享前處理、同時有其他工作；非獨占主機效能基準
A8: vertical085 | B8: s1 | C8: 10 | D8: 58.5 | E8: 2.1213203 | F8: 182.206 | G8: 共享前處理、同時有其他工作；非獨占主機效能基準
A9: vertical085 | B9: s2 | C9: 10 | D9: 64.4 | E9: 2.5473298 | F9: 187.691 | G9: 共享前處理、同時有其他工作；非獨占主機效能基準
A10: vertical085 | B10: s3 | C10: 10 | D10: 52.8 | E10: 2.1499354 | F10: 173.797 | G10: 共享前處理、同時有其他工作；非獨占主機效能基準
A11: vertical085 | B11: s4 | C11: 10 | D11: 59.3 | E11: 2.5407785 | F11: 182.631 | G11: 共享前處理、同時有其他工作；非獨占主機效能基準
A12: vertical085 | B12: s5 | C12: 10 | D12: 83.3 | E12: 2.6267851 | F12: 217.172 | G12: 共享前處理、同時有其他工作；非獨占主機效能基準
A13: vertical085 | B13: s6 | C13: 10 | D13: 95.2 | E13: 2.8205594 | F13: 233.816 | G13: 共享前處理、同時有其他工作；非獨占主機效能基準
... A19: ransac999 | B19: s6 | C19: 10 | D19: 86.6 | E19: 2.836273 | F19: 172.708 | G19: 共享前處理、同時有其他工作；非獨占主機效能基準

Sheet ETH圖選邊
A1: seed | B1: pair | C1: 採用 | D1: 品質score | E1: 3D支持點 | F1: overlap | G1: 中位殘差m
A2: 11 | B2: s1-s2 | C2: 1 | D2: 5.5099745 | E2: 23 | F2: 0.41818182 | G2: 0.074559463
A3: 11 | B3: s1-s3 | C3: 0 | D3: 2.3338915 | E3: 16 | F3: 0.31372549 | G3: 0.1150746
A4: 11 | B4: s1-s4 | C4: 0 | D4: 1.9415417 | E4: 15 | F4: 0.27777778 | G4: 0.11460608
A5: 11 | B5: s1-s5 | C5: 0 | D5: 1.0521209 | E5: 12 | F5: 0.21818182 | G5: 0.14884799
A6: 11 | B6: s1-s6 | C6: 0 | D6: 0 | E6: 0 | F6: 0
A7: 11 | B7: s2-s3 | C7: 0 | D7: 1.3198619 | E7: 12 | F7: 0.23529412 | G7: 0.11392613
A8: 11 | B8: s2-s4 | C8: 0 | D8: 0 | E8: 0 | F8: 0
A9: 11 | B9: s2-s5 | C9: 1 | D9: 4.3664866 | E9: 22 | F9: 0.38596491 | G9: 0.094463625
A10: 11 | B10: s2-s6 | C10: 0 | D10: 0 | E10: 12 | F10: 0.21052632 | G10: 0.23632798
A11: 11 | B11: s3-s4 | C11: 1 | D11: 4.696113 | E11: 21 | F11: 0.41176471 | G11: 0.084132256
A12: 11 | B12: s3-s5 | C12: 0 | D12: 4.0608111 | E12: 20 | F12: 0.39215686 | G12: 0.093142137
A13: 11 | B13: s4-s5 | C13: 1 | D13: 7.2417637 | E13: 29 | F13: 0.53703704 | G13: 0.11505913
A14: 11 | B14: s4-s6 | C14: 1 | D14: 3.6923261 | E14: 21 | F14: 0.38888889 | G14: 0.12117945
A15: 11 | B15: s5-s6 | C15: 0 | D15: 3.4234294 | E15: 26 | F15: 0.325 | G15: 0.14682852
A16: 12 | B16: s1-s2 | C16: 1 | D16: 6.4675643 | E16: 25 | F16: 0.46296296 | G16: 0.078955687
A17: 12 | B17: s1-s3 | C17: 0 | D17: 4.5331375 | E17: 20 | F17: 0.42553191 | G17: 0.087742778
A18: 12 | B18: s1-s4 | C18: 0 | D18: 2.4856191 | E18: 15 | F18: 0.27777778 | G18: 0.067630941
A19: 12 | B19: s1-s5 | C19: 0 | D19: 2.4385316 | E19: 16 | F19: 0.2962963 | G19: 0.094409647
A20: 12 | B20: s1-s6 | C20: 0 | D20: 0.8844324 | E20: 10 | F20: 0.18518519 | G20: 0.10938309
... A34: 13 | B34: s2-s4 | C34: 0 | D34: 2.9408907 | E34: 18 | F34: 0.32142857 | G34: 0.096733402
A35: 13 | B35: s2-s5 | C35: 0 | D35: 0 | E35: 0 | F35: 0
A36: 13 | B36: s2-s6 | C36: 0 | D36: 0.95573261 | E36: 11 | F36: 0.18965517 | G36: 0.11828353
A37: 13 | B37: s3-s4 | C37: 1 | D37: 4.4855505 | E37: 20 | F37: 0.40816327 | G37: 0.081990266
A38: 13 | B38: s4-s5 | C38: 1 | D38: 8.1315027 | E38: 30 | F38: 0.53571429 | G38: 0.097644016
A39: 13 | B39: s4-s6 | C39: 1 | D39: 5.3884241 | E39: 25 | F39: 0.44642857 | G39: 0.1071239
A40: 13 | B40: s5-s6 | C40: 0 | D40: 4.9140038 | E40: 28 | F40: 0.3373494 | G40: 0.092221729
A41: 14 | B41: s1-s3 | C41: 1 | D41: 2.9446656 | E41: 18 | F41: 0.34615385 | G41: 0.11159514
A42: 14 | B42: s1-s5 | C42: 0 | D42: 0 | E42: 0 | F42: 0
A43: 14 | B43: s1-s6 | C43: 0 | D43: 0.4270161 | E43: 7 | F43: 0.13207547 | G43: 0.116509
A44: 14 | B44: s2-s3 | C44: 1 | D44: 5.7605198 | E44: 26 | F44: 0.5 | G44: 0.12567408
A45: 14 | B45: s2-s4 | C45: 0 | D45: 1.5914812 | E45: 13 | F45: 0.22033898 | G45: 0.079983707
A46: 14 | B46: s3-s4 | C46: 0 | D46: 4.9290777 | E46: 22 | F46: 0.42307692 | G46: 0.088832332
A47: 14 | B47: s3-s5 | C47: 1 | D47: 5.660229 | E47: 25 | F47: 0.48076923 | G47: 0.11234531
A48: 14 | B48: s3-s6 | C48: 0 | D48: 2.2583758 | E48: 13 | F48: 0.25 | G48: 0.043908732
A49: 14 | B49: s4-s5 | C49: 1 | D49: 10.16811 | E49: 30 | F49: 0.50847458 | G49: 0.050020384
A50: 14 | B50: s4-s6 | C50: 1 | D50: 6.4198851 | E50: 27 | F50: 0.45762712 | G50: 0.092463448
A51: 14 | B51: s5-s6 | C51: 0 | D51: 3.5138162 | E51: 26 | F51: 0.29213483 | G51: 0.11616115
A52: 15 | B52: s1-s2 | C52: 0 | D52: 4.2582479 | E52: 22 | F52: 0.40740741 | G52: 0.11048476
A53: 15 | B53: s1-s3 | C53: 1 | D53: 7.6193501 | E53: 23 | F53: 0.5 | G53: 0.050931509
...

Sheet 外部提取逐次
A1: 資料版本 | B1: Plot | C1: 論文使用樣區 | D1: 提取設定 | E1: seed | F1: 參考樹數 | G1: 偵測數 | H1: 匹配數 | I1: 參考匹配比例 | J1: 匹配XY RMSE m | K1: 匹配XY中位數m
A2: Liang2018-TreeTool | B2: 1 | C2: =TRUE() -> TRUE | D2: control | E2: 11 | F2: 51 | G2: 44 | H2: 40 | I2: 0.78431373 | J2: 0.035392414 | K2: 0.031352768
A3: Liang2018-TreeTool | B3: 1 | C3: =TRUE() -> TRUE | D3: control | E3: 12 | F3: 51 | G3: 41 | H3: 39 | I3: 0.76470588 | J3: 0.034663829 | K3: 0.030961428
A4: Liang2018-TreeTool | B4: 1 | C4: =TRUE() -> TRUE | D4: control | E4: 13 | F4: 51 | G4: 42 | H4: 39 | I4: 0.76470588 | J4: 0.035296386 | K4: 0.032442719
A5: Liang2018-TreeTool | B5: 1 | C5: =TRUE() -> TRUE | D5: control | E5: 14 | F5: 51 | G5: 43 | H5: 39 | I5: 0.76470588 | J5: 0.038020942 | K5: 0.030961428
A6: Liang2018-TreeTool | B6: 1 | C6: =TRUE() -> TRUE | D6: control | E6: 15 | F6: 51 | G6: 43 | H6: 39 | I6: 0.76470588 | J6: 0.036175516 | K6: 0.031022089
A7: Liang2018-TreeTool | B7: 1 | C7: =TRUE() -> TRUE | D7: control | E7: 16 | F7: 51 | G7: 43 | H7: 40 | I7: 0.78431373 | J7: 0.036042034 | K7: 0.033702172
A8: Liang2018-TreeTool | B8: 1 | C8: =TRUE() -> TRUE | D8: control | E8: 17 | F8: 51 | G8: 44 | H8: 40 | I8: 0.78431373 | J8: 0.034484576 | K8: 0.030725516
A9: Liang2018-TreeTool | B9: 1 | C9: =TRUE() -> TRUE | D9: control | E9: 18 | F9: 51 | G9: 42 | H9: 40 | I9: 0.78431373 | J9: 0.034511683 | K9: 0.031714589
A10: Liang2018-TreeTool | B10: 1 | C10: =TRUE() -> TRUE | D10: control | E10: 19 | F10: 51 | G10: 44 | H10: 39 | I10: 0.76470588 | J10: 0.035682126 | K10: 0.030961428
A11: Liang2018-TreeTool | B11: 1 | C11: =TRUE() -> TRUE | D11: control | E11: 20 | F11: 51 | G11: 44 | H11: 40 | I11: 0.78431373 | J11: 0.035083903 | K11: 0.030181744
A12: Liang2018-TreeTool | B12: 2 | C12: =FALSE() -> FALSE | D12: control | E12: 11 | F12: 84 | G12: 34 | H12: 33 | I12: 0.39285714 | J12: 0.066528643 | K12: 0.05841267
A13: Liang2018-TreeTool | B13: 2 | C13: =FALSE() -> FALSE | D13: control | E13: 12 | F13: 84 | G13: 36 | H13: 35 | I13: 0.41666667 | J13: 0.064141106 | K13: 0.05970134
A14: Liang2018-TreeTool | B14: 2 | C14: =FALSE() -> FALSE | D14: control | E14: 13 | F14: 84 | G14: 37 | H14: 36 | I14: 0.42857143 | J14: 0.06736217 | K14: 0.058401312
A15: Liang2018-TreeTool | B15: 2 | C15: =FALSE() -> FALSE | D15: control | E15: 14 | F15: 84 | G15: 37 | H15: 36 | I15: 0.42857143 | J15: 0.064646429 | K15: 0.057043902
A16: Liang2018-TreeTool | B16: 2 | C16: =FALSE() -> FALSE | D16: control | E16: 15 | F16: 84 | G16: 34 | H16: 34 | I16: 0.4047619 | J16: 0.064876031 | K16: 0.05545338
A17: Liang2018-TreeTool | B17: 2 | C17: =FALSE() -> FALSE | D17: control | E17: 16 | F17: 84 | G17: 37 | H17: 36 | I17: 0.42857143 | J17: 0.064271298 | K17: 0.05415736
A18: Liang2018-TreeTool | B18: 2 | C18: =FALSE() -> FALSE | D18: control | E18: 17 | F18: 84 | G18: 36 | H18: 35 | I18: 0.41666667 | J18: 0.06323269 | K18: 0.056608303
A19: Liang2018-TreeTool | B19: 2 | C19: =FALSE() -> FALSE | D19: control | E19: 18 | F19: 84 | G19: 36 | H19: 36 | I19: 0.42857143 | J19: 0.065965231 | K19: 0.053424049
A20: Liang2018-TreeTool | B20: 2 | C20: =FALSE() -> FALSE | D20: control | E20: 19 | F20: 84 | G20: 36 | H20: 35 | I20: 0.41666667 | J20: 0.064393354 | K20: 0.05492686
A21: Liang2018-TreeTool | B21: 2 | C21: =FALSE() -> FALSE | D21: control | E21: 20 | F21: 84 | G21: 34 | H21: 33 | I21: 0.39285714 | J21: 0.066780888 | K21: 0.062423393
A22: Liang2018-TreeTool | B22: 3 | C22: =TRUE() -> TRUE | D22: control | E22: 11 | F22: 148 | G22: 60 | H22: 60 | I22: 0.40540541 | J22: 0.08476304 | K22: 0.036738895
A23: Liang2018-TreeTool | B23: 3 | C23: =TRUE() -> TRUE | D23: control | E23: 12 | F23: 148 | G23: 59 | H23: 58 | I23: 0.39189189 | J23: 0.082971054 | K23: 0.041943633
A24: Liang2018-TreeTool | B24: 3 | C24: =TRUE() -> TRUE | D24: control | E24: 13 | F24: 148 | G24: 59 | H24: 58 | I24: 0.39189189 | J24: 0.082244255 | K24: 0.039275935
A25: Liang2018-TreeTool | B25: 3 | C25: =TRUE() -> TRUE | D25: control | E25: 14 | F25: 148 | G25: 61 | H25: 59 | I25: 0.39864865 | J25: 0.086996932 | K25: 0.036801223
A26: Liang2018-TreeTool | B26: 3 | C26: =TRUE() -> TRUE | D26: control | E26: 15 | F26: 148 | G26: 63 | H26: 61 | I26: 0.41216216 | J26: 0.080381378 | K26: 0.036632499
A27: Liang2018-TreeTool | B27: 3 | C27: =TRUE() -> TRUE | D27: control | E27: 16 | F27: 148 | G27: 59 | H27: 58 | I27: 0.39189189 | J27: 0.079930822 | K27: 0.0307699
A28: Liang2018-TreeTool | B28: 3 | C28: =TRUE() -> TRUE | D28: control | E28: 17 | F28: 148 | G28: 59 | H28: 58 | I28: 0.39189189 | J28: 0.083025623 | K28: 0.035551354
A29: Liang2018-TreeTool | B29: 3 | C29: =TRUE() -> TRUE | D29: control | E29: 18 | F29: 148 | G29: 56 | H29: 55 | I29: 0.37162162 | J29: 0.085095113 | K29: 0.03592005
A30: Liang2018-TreeTool | B30: 3 | C30: =TRUE() -> TRUE | D30: control | E30: 19 | F30: 148 | G30: 61 | H30: 60 | I30: 0.40540541 | J30: 0.091143007 | K30: 0.042625979
A31: Liang2018-TreeTool | B31: 3 | C31: =TRUE() -> TRUE | D31: control | E31: 20 | F31: 148 | G31: 58 | H31: 57 | I31: 0.38513514 | J31: 0.086155178 | K31: 0.040244875
A32: Liang2018-TreeTool | B32: 4 | C32: =FALSE() -> FALSE | D32: control | E32: 11 | F32: 78 | G32: 36 | H32: 32 | I32: 0.41025641 | J32: 0.058233007 | K32: 0.042607397
A33: Liang2018-TreeTool | B33: 4 | C33: =FALSE() -> FALSE | D33: control | E33: 12 | F33: 78 | G33: 37 | H33: 32 | I33: 0.41025641 | J33: 0.057684048 | K33: 0.042258662
A34: Liang2018-TreeTool | B34: 4 | C34: =FALSE() -> FALSE | D34: control | E34: 13 | F34: 78 | G34: 34 | H34: 32 | I34: 0.41025641 | J34: 0.059944 | K34: 0.043243818
A35: Liang2018-TreeTool | B35: 4 | C35: =FALSE() -> FALSE | D35: control | E35: 14 | F35: 78 | G35: 38 | H35: 34 | I35: 0.43589744 | J35: 0.086117737 | K35: 0.042107451
A36: Liang2018-TreeTool | B36: 4 | C36: =FALSE() -> FALSE | D36: control | E36: 15 | F36: 78 | G36: 37 | H36: 32 | I36: 0.41025641 | J36: 0.054079207 | K36: 0.040714434
A37: Liang2018-TreeTool | B37: 4 | C37: =FALSE() -> FALSE | D37: control | E37: 16 | F37: 78 | G37: 36 | H37: 33 | I37: 0.42307692 | J37: 0.058984507 | K37: 0.042990697
A38: Liang2018-TreeTool | B38: 4 | C38: =FALSE() -> FALSE | D38: control | E38: 17 | F38: 78 | G38: 38 | H38: 33 | I38: 0.42307692 | J38: 0.060205245 | K38: 0.040509999
A39: Liang2018-TreeTool | B39: 4 | C39: =FALSE() -> FALSE | D39: control | E39: 18 | F39: 78 | G39: 36 | H39: 32 | I39: 0.41025641 | J39: 0.060811299 | K39: 0.038288126
A40: Liang2018-TreeTool | B40: 4 | C40: =FALSE() -> FALSE | D40: control | E40: 19 | F40: 78 | G40: 38 | H40: 33 | I40: 0.42307692 | J40: 0.10027278 | K40: 0.042698595
...

Sheet 外部提取摘要
A1: 設定 | B1: Plot | C1: 論文使用樣區 | D1: 參考樹數 | E1: seed數 | F1: 平均偵測數 | G1: 平均匹配數 | H1: 平均參考匹配比例 | I1: seed比例SD | J1: 每seed匹配RMSE中位數m
A2: control | B2: 1 | C2: =TRUE() -> TRUE | D2: 51 | E2: =COUNTIFS(外部提取逐次!$B$2:$B$181,$B2,外部提取逐次!$D$2:$D$181,$A2) -> 10 | F2: =AVERAGEIFS(外部提取逐次!$G$2:$G$181,外部提取逐次!$B$2:$B$181,$B2,外部提取逐次!$D$2:$D$181,$A2) -> 43 | G2: =AVERAGEIFS(外部提取逐次!$H$2:$H$181,外部提取逐次!$B$2:$B$181,$B2,外部提取逐次!$D$2:$D$181,$A2) -> 39.5 | H2: =AVERAGEIFS(外部提取逐次!$I$2:$I$181,外部提取逐次!$B$2:$B$181,$B2,外部提取逐次!$D$2:$D$181,$A2) -> 0.7745098 | I2: 0.010334241 | J2: 0.0353444
A3: control | B3: 2 | C3: =FALSE() -> FALSE | D3: 84 | E3: =COUNTIFS(外部提取逐次!$B$2:$B$181,$B3,外部提取逐次!$D$2:$D$181,$A3) -> 10 | F3: =AVERAGEIFS(外部提取逐次!$G$2:$G$181,外部提取逐次!$B$2:$B$181,$B3,外部提取逐次!$D$2:$D$181,$A3) -> 35.7 | G3: =AVERAGEIFS(外部提取逐次!$H$2:$H$181,外部提取逐次!$B$2:$B$181,$B3,外部提取逐次!$D$2:$D$181,$A3) -> 34.9 | H3: =AVERAGEIFS(外部提取逐次!$I$2:$I$181,外部提取逐次!$B$2:$B$181,$B3,外部提取逐次!$D$2:$D$181,$A3) -> 0.41547619 | I3: 0.014252607 | J3: 0.06476123
A4: control | B4: 3 | C4: =TRUE() -> TRUE | D4: 148 | E4: =COUNTIFS(外部提取逐次!$B$2:$B$181,$B4,外部提取逐次!$D$2:$D$181,$A4) -> 10 | F4: =AVERAGEIFS(外部提取逐次!$G$2:$G$181,外部提取逐次!$B$2:$B$181,$B4,外部提取逐次!$D$2:$D$181,$A4) -> 59.5 | G4: =AVERAGEIFS(外部提取逐次!$H$2:$H$181,外部提取逐次!$B$2:$B$181,$B4,外部提取逐次!$D$2:$D$181,$A4) -> 58.4 | H4: =AVERAGEIFS(外部提取逐次!$I$2:$I$181,外部提取逐次!$B$2:$B$181,$B4,外部提取逐次!$D$2:$D$181,$A4) -> 0.39459459 | I4: 0.011572282 | J4: 0.083894332
A5: control | B5: 4 | C5: =FALSE() -> FALSE | D5: 78 | E5: =COUNTIFS(外部提取逐次!$B$2:$B$181,$B5,外部提取逐次!$D$2:$D$181,$A5) -> 10 | F5: =AVERAGEIFS(外部提取逐次!$G$2:$G$181,外部提取逐次!$B$2:$B$181,$B5,外部提取逐次!$D$2:$D$181,$A5) -> 36.8 | G5: =AVERAGEIFS(外部提取逐次!$H$2:$H$181,外部提取逐次!$B$2:$B$181,$B5,外部提取逐次!$D$2:$D$181,$A5) -> 32.6 | H5: =AVERAGEIFS(外部提取逐次!$I$2:$I$181,外部提取逐次!$B$2:$B$181,$B5,外部提取逐次!$D$2:$D$181,$A5) -> 0.41794872 | I5: 0.0089641782 | J5: 0.059464254
A6: control | B6: 5 | C6: =TRUE() -> TRUE | D6: 131 | E6: =COUNTIFS(外部提取逐次!$B$2:$B$181,$B6,外部提取逐次!$D$2:$D$181,$A6) -> 10 | F6: =AVERAGEIFS(外部提取逐次!$G$2:$G$181,外部提取逐次!$B$2:$B$181,$B6,外部提取逐次!$D$2:$D$181,$A6) -> 22 | G6: =AVERAGEIFS(外部提取逐次!$H$2:$H$181,外部提取逐次!$B$2:$B$181,$B6,外部提取逐次!$D$2:$D$181,$A6) -> 19 | H6: =AVERAGEIFS(外部提取逐次!$I$2:$I$181,外部提取逐次!$B$2:$B$181,$B6,外部提取逐次!$D$2:$D$181,$A6) -> 0.14503817 | I6: 0.010178117 | J6: 0.10476662
A7: control | B7: 6 | C7: =FALSE() -> FALSE | D7: 236 | E7: =COUNTIFS(外部提取逐次!$B$2:$B$181,$B7,外部提取逐次!$D$2:$D$181,$A7) -> 10 | F7: =AVERAGEIFS(外部提取逐次!$G$2:$G$181,外部提取逐次!$B$2:$B$181,$B7,外部提取逐次!$D$2:$D$181,$A7) -> 40 | G7: =AVERAGEIFS(外部提取逐次!$H$2:$H$181,外部提取逐次!$B$2:$B$181,$B7,外部提取逐次!$D$2:$D$181,$A7) -> 36 | H7: =AVERAGEIFS(外部提取逐次!$I$2:$I$181,外部提取逐次!$B$2:$B$181,$B7,外部提取逐次!$D$2:$D$181,$A7) -> 0.15254237 | I7: 0.0063165762 | J7: 0.066946861
A8: vertical085 | B8: 1 | C8: =TRUE() -> TRUE | D8: 51 | E8: =COUNTIFS(外部提取逐次!$B$2:$B$181,$B8,外部提取逐次!$D$2:$D$181,$A8) -> 10 | F8: =AVERAGEIFS(外部提取逐次!$G$2:$G$181,外部提取逐次!$B$2:$B$181,$B8,外部提取逐次!$D$2:$D$181,$A8) -> 42 | G8: =AVERAGEIFS(外部提取逐次!$H$2:$H$181,外部提取逐次!$B$2:$B$181,$B8,外部提取逐次!$D$2:$D$181,$A8) -> 38.1 | H8: =AVERAGEIFS(外部提取逐次!$I$2:$I$181,外部提取逐次!$B$2:$B$181,$B8,外部提取逐次!$D$2:$D$181,$A8) -> 0.74705882 | I8: 0.011130318 | J8: 0.035838398
A9: vertical085 | B9: 2 | C9: =FALSE() -> FALSE | D9: 84 | E9: =COUNTIFS(外部提取逐次!$B$2:$B$181,$B9,外部提取逐次!$D$2:$D$181,$A9) -> 10 | F9: =AVERAGEIFS(外部提取逐次!$G$2:$G$181,外部提取逐次!$B$2:$B$181,$B9,外部提取逐次!$D$2:$D$181,$A9) -> 32.1 | G9: =AVERAGEIFS(外部提取逐次!$H$2:$H$181,外部提取逐次!$B$2:$B$181,$B9,外部提取逐次!$D$2:$D$181,$A9) -> 31.3 | H9: =AVERAGEIFS(外部提取逐次!$I$2:$I$181,外部提取逐次!$B$2:$B$181,$B9,外部提取逐次!$D$2:$D$181,$A9) -> 0.37261905 | I9: 0.0098008643 | J9: 0.06908396
A10: vertical085 | B10: 3 | C10: =TRUE() -> TRUE | D10: 148 | E10: =COUNTIFS(外部提取逐次!$B$2:$B$181,$B10,外部提取逐次!$D$2:$D$181,$A10) -> 10 | F10: =AVERAGEIFS(外部提取逐次!$G$2:$G$181,外部提取逐次!$B$2:$B$181,$B10,外部提取逐次!$D$2:$D$181,$A10) -> 50.4 | G10: =AVERAGEIFS(外部提取逐次!$H$2:$H$181,外部提取逐次!$B$2:$B$181,$B10,外部提取逐次!$D$2:$D$181,$A10) -> 47.1 | H10: =AVERAGEIFS(外部提取逐次!$I$2:$I$181,外部提取逐次!$B$2:$B$181,$B10,外部提取逐次!$D$2:$D$181,$A10) -> 0.31824324 | I10: 0.0067191144 | J10: 0.052501244
A11: vertical085 | B11: 4 | C11: =FALSE() -> FALSE | D11: 78 | E11: =COUNTIFS(外部提取逐次!$B$2:$B$181,$B11,外部提取逐次!$D$2:$D$181,$A11) -> 10 | F11: =AVERAGEIFS(外部提取逐次!$G$2:$G$181,外部提取逐次!$B$2:$B$181,$B11,外部提取逐次!$D$2:$D$181,$A11) -> 36.2 | G11: =AVERAGEIFS(外部提取逐次!$H$2:$H$181,外部提取逐次!$B$2:$B$181,$B11,外部提取逐次!$D$2:$D$181,$A11) -> 31.4 | H11: =AVERAGEIFS(外部提取逐次!$I$2:$I$181,外部提取逐次!$B$2:$B$181,$B11,外部提取逐次!$D$2:$D$181,$A11) -> 0.4025641 | I11: 0.010811206 | J11: 0.064226651
A12: vertical085 | B12: 5 | C12: =TRUE() -> TRUE | D12: 131 | E12: =COUNTIFS(外部提取逐次!$B$2:$B$181,$B12,外部提取逐次!$D$2:$D$181,$A12) -> 10 | F12: =AVERAGEIFS(外部提取逐次!$G$2:$G$181,外部提取逐次!$B$2:$B$181,$B12,外部提取逐次!$D$2:$D$181,$A12) -> 20 | G12: =AVERAGEIFS(外部提取逐次!$H$2:$H$181,外部提取逐次!$B$2:$B$181,$B12,外部提取逐次!$D$2:$D$181,$A12) -> 15.6 | H12: =AVERAGEIFS(外部提取逐次!$I$2:$I$181,外部提取逐次!$B$2:$B$181,$B12,外部提取逐次!$D$2:$D$181,$A12) -> 0.11908397 | I12: 0.0064372064 | J12: 0.10772755
