Workbook

Sheet 最新說明
A1: 項目 | B1: 內容
A2: 內容範圍 | B2: 保留前輪ETH參數與六站研究、Liang外部提取，另加入本輪完整兩站補救比較。
A3: 最新驗證 | B3: seed21–30：600列＝兩種方法×兩種solver×150個配對案例；主要比較為svd+ransac。
A4: 本輪主要結果 | B4: 原推薦組142/150，加補救後150/150；官方列表98/100→100/100，補回8次、退步0次。
A5: 改動 | B5: 少於6對匹配時，收集前三個描述子候選的證據，使用完整3D一致性補救；推論不讀GT。
A6: 保持固定 | B6: step距離降採樣、clustering0.20m、垂直度0.90、匹配閾值0.10m、配準RANSAC。
A7: 新功能預設 | B7: 補救預設關閉，須指定--recovery=evidence --recovery_trigger=6。
A8: 資料分工 | B8: seed11–20用於本輪診斷與選方案；之後固定程式及參數，才產生seed21–30驗證。
A9: 舊seed候選 | B9: 1200列＝四種候選（含原推薦組）×兩種solver×150案例；已用於選方案，不能再視為盲測。
A10: 舊seed點雲誤差 | B10: 候選篩選省略原始點雲讀取與e_p；空白為未計算，不是零誤差。新驗證則計算完整source點雲e_p。
A11: 工作表閱讀 | B11: 本輪工作表排在前面；「說明」起的原17張工作表保留前輪資料及其原本seed範圍。
A12: 成功定義 | B12: 旋轉誤差<2°且平移誤差<0.5m；與前輪相同。
... A18: 精簡版 | B18: 同目錄comparison_simple.xlsx；使用同一批seed21–30驗證數據。

Sheet 新驗證摘要
A1: 方法 | B1: solver | C1: 案例數 | D1: 成功數 | E1: 成功率 | F1: 官方案例數 | G1: 官方成功數 | H1: 官方成功率 | I1: 成功e_p中位數m | J1: 平均匹配求解ms | K1: 匹配求解中位數ms | L1: 匹配求解p95 ms | M1: 觸發補救數 | N1: 採用補救數
A2: baseline | B2: svd | C2: =COUNTIFS(新驗證逐次!$A$2:$A$601,A2,新驗證逐次!$B$2:$B$601,B2) -> 150 | D2: =COUNTIFS(新驗證逐次!$A$2:$A$601,A2,新驗證逐次!$B$2:$B$601,B2,新驗證逐次!$AE$2:$AE$601,1) -> 139 | E2: =D2/C2 -> 0.92666667 | F2: =COUNTIFS(新驗證逐次!$A$2:$A$601,A2,新驗證逐次!$B$2:$B$601,B2,新驗證逐次!$E$2:$E$601,1) -> 100 | G2: =COUNTIFS(新驗證逐次!$A$2:$A$601,A2,新驗證逐次!$B$2:$B$601,B2,新驗證逐次!$E$2:$E$601,1,新驗證逐次!$AE$2:$AE$601,1) -> 96 | H2: =G2/F2 -> 0.96 | I2: 0.072332999 | J2: 3.3780498 | K2: 3.0732705 | L2: 5.424482 | M2: 0 | N2: 0
A3: baseline | B3: svd+ransac | C3: =COUNTIFS(新驗證逐次!$A$2:$A$601,A3,新驗證逐次!$B$2:$B$601,B3) -> 150 | D3: =COUNTIFS(新驗證逐次!$A$2:$A$601,A3,新驗證逐次!$B$2:$B$601,B3,新驗證逐次!$AE$2:$AE$601,1) -> 142 | E3: =D3/C3 -> 0.94666667 | F3: =COUNTIFS(新驗證逐次!$A$2:$A$601,A3,新驗證逐次!$B$2:$B$601,B3,新驗證逐次!$E$2:$E$601,1) -> 100 | G3: =COUNTIFS(新驗證逐次!$A$2:$A$601,A3,新驗證逐次!$B$2:$B$601,B3,新驗證逐次!$E$2:$E$601,1,新驗證逐次!$AE$2:$AE$601,1) -> 98 | H3: =G3/F3 -> 0.98 | I3: 0.067380268 | J3: 4.3470339 | K3: 3.934507 | L3: 6.503743 | M3: 0 | N3: 0
A4: recovery | B4: svd | C4: =COUNTIFS(新驗證逐次!$A$2:$A$601,A4,新驗證逐次!$B$2:$B$601,B4) -> 150 | D4: =COUNTIFS(新驗證逐次!$A$2:$A$601,A4,新驗證逐次!$B$2:$B$601,B4,新驗證逐次!$AE$2:$AE$601,1) -> 147 | E4: =D4/C4 -> 0.98 | F4: =COUNTIFS(新驗證逐次!$A$2:$A$601,A4,新驗證逐次!$B$2:$B$601,B4,新驗證逐次!$E$2:$E$601,1) -> 100 | G4: =COUNTIFS(新驗證逐次!$A$2:$A$601,A4,新驗證逐次!$B$2:$B$601,B4,新驗證逐次!$E$2:$E$601,1,新驗證逐次!$AE$2:$AE$601,1) -> 98 | H4: =G4/F4 -> 0.98 | I4: 0.071110935 | J4: 4.7154728 | K4: 3.130736 | L4: 10.632216 | M4: 31 | N4: 31
A5: recovery | B5: svd+ransac | C5: =COUNTIFS(新驗證逐次!$A$2:$A$601,A5,新驗證逐次!$B$2:$B$601,B5) -> 150 | D5: =COUNTIFS(新驗證逐次!$A$2:$A$601,A5,新驗證逐次!$B$2:$B$601,B5,新驗證逐次!$AE$2:$AE$601,1) -> 150 | E5: =D5/C5 -> 1 | F5: =COUNTIFS(新驗證逐次!$A$2:$A$601,A5,新驗證逐次!$B$2:$B$601,B5,新驗證逐次!$E$2:$E$601,1) -> 100 | G5: =COUNTIFS(新驗證逐次!$A$2:$A$601,A5,新驗證逐次!$B$2:$B$601,B5,新驗證逐次!$E$2:$E$601,1,新驗證逐次!$AE$2:$AE$601,1) -> 100 | H5: =G5/F5 -> 1 | I5: 0.063653641 | J5: 5.5307042 | K5: 3.9122135 | L5: 11.661867 | M5: 31 | N5: 31

Sheet 新驗證逐次
A1: method | B1: solver | C1: seed | D1: pair | E1: official | F1: label | G1: threshold | H1: setting | I1: n_src_kp | J1: n_tgt_kp | K1: descriptors_src | L1: descriptors_tgt | M1: d12_enc2_s0_is_p1 | N1: d12_enc3_s0_is_p1p2 | O1: gate_passed | P1: candidates | Q1: best_score | R1: best_dc | S1: best_fm | T1: used_triangle | U1: tri_set_src | V1: tri_set_tgt | W1: tri_matches | X1: n_matches | Y1: n_correct_matches | Z1: ransac_inliers | AA1: transform_ok | AB1: rot_err_deg | AC1: trans_err_m | AD1: e_p_m | AE1: success | AF1: time_ms | AG1: r00 | AH1: r01 | AI1: r02 | AJ1: r10 | AK1: r11 | AL1: r12 | AM1: r20 | AN1: r21 | AO1: r22 | AP1: t0 | AQ1: t1 | AR1: t2 | AS1: recovery | AT1: recovery_triggered | AU1: recovery_accepted | AV1: recovery_hypotheses | AW1: recovery_support | AX1: recovery_median_m
A2: baseline | B2: svd | C2: 21 | D2: s1-s2 | E2: 1 | F2: 21_s1-s2 | G2: 0.1 | H2: sensitivity(not paper) | I2: 54 | J2: 60 | K2: 54 | L2: 60 | M2: 5 | N2: 9 | O2: 306 | P2: 12 | Q2: 111 | R2: 11 | S2: 10 | T2: 0 | U2: 0 | V2: 0 | W2: 0 | X2: 9 | Y2: 9 | Z2: 0 | AA2: 1 | AB2: 0.24334578 | AC2: 0.046617757 | AD2: 0.048794776 | AE2: 1 | AF2: 3.02073 | AG2: -0.71875906 | AH2: -0.69524307 | AI2: 0.0047421651 | AJ2: 0.69524829 | AK2: -0.7187693 | AL2: -0.00071185772 | AM2: 0.0039034368 | AN2: 0.002785328 | AO2: 0.9999885 | AP2: -11.076481 | AQ2: -0.87976367 | AR2: 0.58003899
A3: baseline | B3: svd+ransac | C3: 21 | D3: s1-s2 | E3: 1 | F3: 21_s1-s2 | G3: 0.1 | H3: sensitivity(not paper) | I3: 54 | J3: 60 | K3: 54 | L3: 60 | M3: 5 | N3: 9 | O3: 306 | P3: 12 | Q3: 111 | R3: 11 | S3: 10 | T3: 0 | U3: 0 | V3: 0 | W3: 0 | X3: 9 | Y3: 9 | Z3: 9 | AA3: 1 | AB3: 0.24334578 | AC3: 0.046617757 | AD3: 0.048794776 | AE3: 1 | AF3: 4.397297 | AG3: -0.71875906 | AH3: -0.69524307 | AI3: 0.0047421651 | AJ3: 0.69524829 | AK3: -0.7187693 | AL3: -0.00071185772 | AM3: 0.0039034368 | AN3: 0.002785328 | AO3: 0.9999885 | AP3: -11.076481 | AQ3: -0.87976367 | AR3: 0.58003899
A4: baseline | B4: svd | C4: 21 | D4: s1-s3 | E4: 1 | F4: 21_s1-s3 | G4: 0.1 | H4: sensitivity(not paper) | I4: 54 | J4: 48 | K4: 54 | L4: 48 | M4: 4 | N4: 8 | O4: 199 | P4: 11 | Q4: 155 | R4: 5 | S4: 15 | T4: 0 | U4: 0 | V4: 0 | W4: 0 | X4: 11 | Y4: 11 | Z4: 0 | AA4: 1 | AB4: 0.6488976 | AC4: 0.031643763 | AD4: 0.046881893 | AE4: 1 | AF4: 2.370908 | AG4: 0.9338585 | AH4: 0.35756912 | AI4: -0.0072545448 | AJ4: -0.35753125 | AK4: 0.93388176 | AL4: 0.0060209877 | AM4: 0.0089278063 | AN4: -0.0030290241 | AO4: 0.99995556 | AP4: 8.3919229 | AQ4: 1.3841447 | AR4: 0.68182258
A5: baseline | B5: svd+ransac | C5: 21 | D5: s1-s3 | E5: 1 | F5: 21_s1-s3 | G5: 0.1 | H5: sensitivity(not paper) | I5: 54 | J5: 48 | K5: 54 | L5: 48 | M5: 4 | N5: 8 | O5: 199 | P5: 11 | Q5: 155 | R5: 5 | S5: 15 | T5: 0 | U5: 0 | V5: 0 | W5: 0 | X5: 11 | Y5: 11 | Z5: 11 | AA5: 1 | AB5: 0.6488976 | AC5: 0.031643763 | AD5: 0.046881893 | AE5: 1 | AF5: 5.628759 | AG5: 0.9338585 | AH5: 0.35756912 | AI5: -0.0072545448 | AJ5: -0.35753125 | AK5: 0.93388176 | AL5: 0.0060209877 | AM5: 0.0089278063 | AN5: -0.0030290241 | AO5: 0.99995556 | AP5: 8.3919229 | AQ5: 1.3841447 | AR5: 0.68182258
A6: baseline | B6: svd | C6: 21 | D6: s1-s4 | E6: 0 | F6: 21_s1-s4 | G6: 0.1 | H6: sensitivity(not paper) | I6: 54 | J6: 51 | K6: 54 | L6: 51 | M6: 4 | N6: 8 | O6: 221 | P6: 5 | Q6: 59 | R6: 9 | S6: 5 | T6: 0 | U6: 0 | V6: 0 | W6: 0 | X6: 5 | Y6: 5 | Z6: 0 | AA6: 1 | AB6: 0.9651024 | AC6: 0.16599487 | AD6: 0.17584513 | AE6: 1 | AF6: 2.758593 | AG6: 0.90222477 | AH6: 0.43101311 | AI6: -0.014770273 | AJ6: -0.43113321 | AK6: 0.9022678 | AL6: -0.0060802343 | AM6: 0.010706081 | AN6: 0.011853693 | AO6: 0.99987243 | AP6: 22.837754 | AQ6: 6.5281208 | AR6: 1.5680333
A7: baseline | B7: svd+ransac | C7: 21 | D7: s1-s4 | E7: 0 | F7: 21_s1-s4 | G7: 0.1 | H7: sensitivity(not paper) | I7: 54 | J7: 51 | K7: 54 | L7: 51 | M7: 4 | N7: 8 | O7: 221 | P7: 5 | Q7: 59 | R7: 9 | S7: 5 | T7: 0 | U7: 0 | V7: 0 | W7: 0 | X7: 5 | Y7: 5 | Z7: 5 | AA7: 1 | AB7: 0.9651024 | AC7: 0.16599487 | AD7: 0.17584513 | AE7: 1 | AF7: 3.575995 | AG7: 0.90222477 | AH7: 0.43101311 | AI7: -0.014770273 | AJ7: -0.43113321 | AK7: 0.9022678 | AL7: -0.0060802343 | AM7: 0.010706081 | AN7: 0.011853693 | AO7: 0.99987243 | AP7: 22.837754 | AQ7: 6.5281208 | AR7: 1.5680333
A8: baseline | B8: svd | C8: 21 | D8: s1-s5 | E8: 0 | F8: 21_s1-s5 | G8: 0.1 | H8: sensitivity(not paper) | I8: 54 | J8: 82 | K8: 54 | L8: 82 | M8: 8 | N8: 13 | O8: 452 | P8: 10 | Q8: 80 | R8: 10 | S8: 7 | T8: 0 | U8: 0 | V8: 0 | W8: 0 | X8: 6 | Y8: 6 | Z8: 0 | AA8: 1 | AB8: 0.62494031 | AC8: 0.11881743 | AD8: 0.12681781 | AE8: 1 | AF8: 3.312327 | AG8: 0.22466187 | AH8: -0.97440097 | AI8: -0.008354243 | AJ8: 0.97440311 | AK8: 0.22471712 | AL8: -0.0063865856 | AM8: 0.0081004367 | AN8: -0.0067055781 | AO8: 0.99994471 | AP8: -16.502891 | AQ8: 20.505421 | AR8: 0.88708549
A9: baseline | B9: svd+ransac | C9: 21 | D9: s1-s5 | E9: 0 | F9: 21_s1-s5 | G9: 0.1 | H9: sensitivity(not paper) | I9: 54 | J9: 82 | K9: 54 | L9: 82 | M9: 8 | N9: 13 | O9: 452 | P9: 10 | Q9: 80 | R9: 10 | S9: 7 | T9: 0 | U9: 0 | V9: 0 | W9: 0 | X9: 6 | Y9: 6 | Z9: 6 | AA9: 1 | AB9: 0.62494031 | AC9: 0.11881743 | AD9: 0.12681781 | AE9: 1 | AF9: 3.963989 | AG9: 0.22466187 | AH9: -0.97440097 | AI9: -0.008354243 | AJ9: 0.97440311 | AK9: 0.22471712 | AL9: -0.0063865856 | AM9: 0.0081004367 | AN9: -0.0067055781 | AO9: 0.99994471 | AP9: -16.502891 | AQ9: 20.505421 | AR9: 0.88708549
A10: baseline | B10: svd | C10: 21 | D10: s1-s6 | E10: 0 | F10: 21_s1-s6 | G10: 0.1 | H10: sensitivity(not paper) | I10: 54 | J10: 92 | K10: 54 | L10: 92 | M10: 5 | N10: 14 | O10: 395 | P10: 5 | Q10: 26 | R10: 6 | S10: 2 | T10: 1 | U10: 6 | V10: 6 | W10: 11 | X10: 6 | Y10: 6 | Z10: 0 | AA10: 1 | AB10: 1.542428 | AC10: 0.19631537 | AD10: 0.21472741 | AE10: 1 | AF10: 5.710917 | AG10: 0.98862944 | AH10: 0.14870962 | AI10: -0.022299661 | AJ10: -0.14848264 | AK10: 0.98884791 | AL10: 0.011520011 | AM10: 0.02376411 | AN10: -0.0080779099 | AO10: 0.99968496 | AP10: 25.100199 | AQ10: 19.821357 | AR10: 2.2748919
A11: baseline | B11: svd+ransac | C11: 21 | D11: s1-s6 | E11: 0 | F11: 21_s1-s6 | G11: 0.1 | H11: sensitivity(not paper) | I11: 54 | J11: 92 | K11: 54 | L11: 92 | M11: 5 | N11: 14 | O11: 395 | P11: 5 | Q11: 26 | R11: 6 | S11: 2 | T11: 1 | U11: 6 | V11: 6 | W11: 11 | X11: 6 | Y11: 6 | Z11: 6 | AA11: 1 | AB11: 1.542428 | AC11: 0.19631537 | AD11: 0.21472741 | AE11: 1 | AF11: 6.386465 | AG11: 0.98862944 | AH11: 0.14870962 | AI11: -0.022299661 | AJ11: -0.14848264 | AK11: 0.98884791 | AL11: 0.011520011 | AM11: 0.02376411 | AN11: -0.0080779099 | AO11: 0.99968496 | AP11: 25.100199 | AQ11: 19.821357 | AR11: 2.2748919
A12: baseline | B12: svd | C12: 22 | D12: s1-s2 | E12: 1 | F12: 22_s1-s2 | G12: 0.1 | H12: sensitivity(not paper) | I12: 56 | J12: 61 | K12: 56 | L12: 61 | M12: 4 | N12: 11 | O12: 319 | P12: 11 | Q12: 83 | R12: 23 | S12: 6 | T12: 0 | U12: 0 | V12: 0 | W12: 0 | X12: 5 | Y12: 5 | Z12: 0 | AA12: 1 | AB12: 0.41484024 | AC12: 0.11770101 | AD12: 0.12147746 | AE12: 1 | AF12: 2.444122 | AG12: -0.71707853 | AH12: -0.69698166 | AI12: -0.0038672388 | AJ12: 0.69698886 | AK12: -0.7170462 | AL12: -0.007161253 | AM12: 0.0022182731 | AN12: -0.0078306031 | AO12: 0.99996688 | AP12: -11.126673 | AQ12: -0.85474771 | AR12: 0.42810177
A13: baseline | B13: svd+ransac | C13: 22 | D13: s1-s2 | E13: 1 | F13: 22_s1-s2 | G13: 0.1 | H13: sensitivity(not paper) | I13: 56 | J13: 61 | K13: 56 | L13: 61 | M13: 4 | N13: 11 | O13: 319 | P13: 11 | Q13: 83 | R13: 23 | S13: 6 | T13: 0 | U13: 0 | V13: 0 | W13: 0 | X13: 5 | Y13: 5 | Z13: 5 | AA13: 1 | AB13: 0.41484024 | AC13: 0.11770101 | AD13: 0.12147746 | AE13: 1 | AF13: 3.033106 | AG13: -0.71707853 | AH13: -0.69698166 | AI13: -0.0038672388 | AJ13: 0.69698886 | AK13: -0.7170462 | AL13: -0.007161253 | AM13: 0.0022182731 | AN13: -0.0078306031 | AO13: 0.99996688 | AP13: -11.126673 | AQ13: -0.85474771 | AR13: 0.42810177
... A25: baseline | B25: svd+ransac | C25: 23 | D25: s1-s3 | E25: 1 | F25: 23_s1-s3 | G25: 0.1 | H25: sensitivity(not paper) | I25: 59 | J25: 50 | K25: 59 | L25: 50 | M25: 3 | N25: 10 | O25: 296 | P25: 12 | Q25: 134 | R25: 24 | S25: 11 | T25: 0 | U25: 0 | V25: 0 | W25: 0 | X25: 10 | Y25: 10 | Z25: 9 | AA25: 1 | AB25: 0.86998109 | AC25: 0.036575895 | AD25: 0.062435512 | AE25: 1 | AF25: 3.149278 | AG25: 0.93402941 | AH25: 0.35706791 | AI25: -0.0095687414 | AJ25: -0.35698699 | AK25: 0.93406412 | AL25: 0.0091931448 | AM25: 0.012220395 | AN25: -0.0051707514 | AO25: 0.99991196 | AP25: 8.3792432 | AQ25: 1.3722301 | AR25: 0.67699776
A26: baseline | B26: svd | C26: 23 | D26: s1-s4 | E26: 0 | F26: 23_s1-s4 | G26: 0.1 | H26: sensitivity(not paper) | I26: 59 | J26: 54 | K26: 59 | L26: 54 | M26: 2 | N26: 7 | O26: 229 | P26: 6 | Q26: 60 | R26: 10 | S26: 5 | T26: 0 | U26: 0 | V26: 0 | W26: 0 | X26: 2 | Y26: 2 | Z26: 0 | AA26: 0 | AE26: 0 | AF26: 3.255293 | AG26: 1 | AH26: 0 | AI26: 0 | AJ26: 0 | AK26: 1 | AL26: 0 | AM26: 0 | AN26: 0 | AO26: 1 | AP26: 0 | AQ26: 0 | AR26: 0
A27: baseline | B27: svd+ransac | C27: 23 | D27: s1-s4 | E27: 0 | F27: 23_s1-s4 | G27: 0.1 | H27: sensitivity(not paper) | I27: 59 | J27: 54 | K27: 59 | L27: 54 | M27: 2 | N27: 7 | O27: 229 | P27: 6 | Q27: 60 | R27: 10 | S27: 5 | T27: 0 | U27: 0 | V27: 0 | W27: 0 | X27: 2 | Y27: 2 | Z27: 0 | AA27: 0 | AE27: 0 | AF27: 3.255063 | AG27: 1 | AH27: 0 | AI27: 0 | AJ27: 0 | AK27: 1 | AL27: 0 | AM27: 0 | AN27: 0 | AO27: 1 | AP27: 0 | AQ27: 0 | AR27: 0
A28: baseline | B28: svd | C28: 23 | D28: s1-s5 | E28: 0 | F28: 23_s1-s5 | G28: 0.1 | H28: sensitivity(not paper) | I28: 59 | J28: 84 | K28: 59 | L28: 84 | M28: 5 | N28: 18 | O28: 523 | P28: 10 | Q28: 69 | R28: 9 | S28: 6 | T28: 0 | U28: 0 | V28: 0 | W28: 0 | X28: 4 | Y28: 4 | Z28: 0 | AA28: 1 | AB28: 0.29989551 | AC28: 0.070531754 | AD28: 0.071636022 | AE28: 1 | AF28: 4.30584 | AG28: 0.22545292 | AH28: -0.97425396 | AI28: 0.000438209 | AJ28: 0.97423269 | AK28: 0.22544497 | AL28: -0.0067259834 | AM28: 0.006454024 | AN28: 0.0019433101 | AO28: 0.99997728 | AP28: -16.520908 | AQ28: 20.516821 | AR28: 1.0656625
A29: baseline | B29: svd+ransac | C29: 23 | D29: s1-s5 | E29: 0 | F29: 23_s1-s5 | G29: 0.1 | H29: sensitivity(not paper) | I29: 59 | J29: 84 | K29: 59 | L29: 84 | M29: 5 | N29: 18 | O29: 523 | P29: 10 | Q29: 69 | R29: 9 | S29: 6 | T29: 0 | U29: 0 | V29: 0 | W29: 0 | X29: 4 | Y29: 4 | Z29: 4 | AA29: 1 | AB29: 0.29989551 | AC29: 0.070531754 | AD29: 0.071636022 | AE29: 1 | AF29: 5.085864 | AG29: 0.22545292 | AH29: -0.97425396 | AI29: 0.000438209 | AJ29: 0.97423269 | AK29: 0.22544497 | AL29: -0.0067259834 | AM29: 0.006454024 | AN29: 0.0019433101 | AO29: 0.99997728 | AP29: -16.520908 | AQ29: 20.516821 | AR29: 1.0656625
A30: baseline | B30: svd | C30: 23 | D30: s1-s6 | E30: 0 | F30: 23_s1-s6 | G30: 0.1 | H30: sensitivity(not paper) | I30: 59 | J30: 88 | K30: 59 | L30: 88 | M30: 3 | N30: 11 | O30: 395 | P30: 12 | Q30: 29 | R30: 9 | S30: 2 | T30: 1 | U30: 9 | V30: 9 | W30: 48 | X30: 9 | Y30: 9 | Z30: 0 | AA30: 1 | AB30: 1.1468057 | AC30: 0.11293588 | AD30: 0.13353222 | AE30: 1 | AF30: 4.308941 | AG30: 0.98908189 | AH30: 0.14639676 | AI30: -0.016881772 | AJ30: -0.14629675 | AK30: 0.98921583 | AL30: 0.0070208043 | AM30: 0.01772754 | AN30: -0.004474402 | AO30: 0.99983284 | AP30: 25.126614 | AQ30: 19.808271 | AR30: 2.1951162
A31: baseline | B31: svd+ransac | C31: 23 | D31: s1-s6 | E31: 0 | F31: 23_s1-s6 | G31: 0.1 | H31: sensitivity(not paper) | I31: 59 | J31: 88 | K31: 59 | L31: 88 | M31: 3 | N31: 11 | O31: 395 | P31: 12 | Q31: 29 | R31: 9 | S31: 2 | T31: 1 | U31: 9 | V31: 9 | W31: 48 | X31: 9 | Y31: 9 | Z31: 9 | AA31: 1 | AB31: 1.1468057 | AC31: 0.11293588 | AD31: 0.13353222 | AE31: 1 | AF31: 5.298401 | AG31: 0.98908189 | AH31: 0.14639676 | AI31: -0.016881772 | AJ31: -0.14629675 | AK31: 0.98921583 | AL31: 0.0070208043 | AM31: 0.01772754 | AN31: -0.004474402 | AO31: 0.99983284 | AP31: 25.126614 | AQ31: 19.808271 | AR31: 2.1951162
A32: baseline | B32: svd | C32: 24 | D32: s1-s2 | E32: 1 | F32: 24_s1-s2 | G32: 0.1 | H32: sensitivity(not paper) | I32: 58 | J32: 63 | K32: 58 | L32: 63 | M32: 3 | N32: 12 | O32: 341 | P32: 13 | Q32: 123 | R32: 33 | S32: 9 | T32: 0 | U32: 0 | V32: 0 | W32: 0 | X32: 11 | Y32: 11 | Z32: 0 | AA32: 1 | AB32: 0.35039368 | AC32: 0.052659923 | AD32: 0.056307363 | AE32: 1 | AF32: 3.297834 | AG32: -0.71838867 | AH32: -0.69562216 | AI32: 0.005247119 | AJ32: 0.69559609 | AK32: -0.71840748 | AL32: -0.0060631833 | AM32: 0.0079872542 | AN32: -0.00070584666 | AO32: 0.99996785 | AP32: -11.068632 | AQ32: -0.87514759 | AR32: 0.58214066
A33: baseline | B33: svd+ransac | C33: 24 | D33: s1-s2 | E33: 1 | F33: 24_s1-s2 | G33: 0.1 | H33: sensitivity(not paper) | I33: 58 | J33: 63 | K33: 58 | L33: 63 | M33: 3 | N33: 12 | O33: 341 | P33: 13 | Q33: 123 | R33: 33 | S33: 9 | T33: 0 | U33: 0 | V33: 0 | W33: 0 | X33: 11 | Y33: 11 | Z33: 11 | AA33: 1 | AB33: 0.35039368 | AC33: 0.052659923 | AD33: 0.056307363 | AE33: 1 | AF33: 4.586489 | AG33: -0.71838867 | AH33: -0.69562216 | AI33: 0.005247119 | AJ33: 0.69559609 | AK33: -0.71840748 | AL33: -0.0060631833 | AM33: 0.0079872542 | AN33: -0.00070584666 | AO33: 0.99996785 | AP33: -11.068632 | AQ33: -0.87514759 | AR33: 0.58214066
A34: baseline | B34: svd | C34: 24 | D34: s1-s3 | E34: 1 | F34: 24_s1-s3 | G34: 0.1 | H34: sensitivity(not paper) | I34: 58 | J34: 47 | K34: 58 | L34: 47 | M34: 4 | N34: 4 | O34: 205 | P34: 13 | Q34: 178 | R34: 8 | S34: 17 | T34: 0 | U34: 0 | V34: 0 | W34: 0 | X34: 12 | Y34: 12 | Z34: 0 | AA34: 1 | AB34: 0.46205134 | AC34: 0.050946308 | AD34: 0.057369484 | AE34: 1 | AF34: 3.084556 | AG34: 0.9344044 | AH34: 0.35619061 | AI34: -0.0040822401 | AJ34: -0.35617292 | AK34: 0.93440933 | AL34: 0.0044793197 | AM34: 0.0054099748 | AN34: -0.0027315126 | AO34: 0.99998164 | AP34: 8.3822563 | AQ34: 1.3957996 | AR34: 0.64272871
A35: baseline | B35: svd+ransac | C35: 24 | D35: s1-s3 | E35: 1 | F35: 24_s1-s3 | G35: 0.1 | H35: sensitivity(not paper) | I35: 58 | J35: 47 | K35: 58 | L35: 47 | M35: 4 | N35: 4 | O35: 205 | P35: 13 | Q35: 178 | R35: 8 | S35: 17 | T35: 0 | U35: 0 | V35: 0 | W35: 0 | X35: 12 | Y35: 12 | Z35: 12 | AA35: 1 | AB35: 0.46205134 | AC35: 0.050946308 | AD35: 0.057369484 | AE35: 1 | AF35: 4.023644 | AG35: 0.9344044 | AH35: 0.35619061 | AI35: -0.0040822401 | AJ35: -0.35617292 | AK35: 0.93440933 | AL35: 0.0044793197 | AM35: 0.0054099748 | AN35: -0.0027315126 | AO35: 0.99998164 | AP35: 8.3822563 | AQ35: 1.3957996 | AR35: 0.64272871
A36: baseline | B36: svd | C36: 24 | D36: s1-s4 | E36: 0 | F36: 24_s1-s4 | G36: 0.1 | H36: sensitivity(not paper) | I36: 58 | J36: 58 | K36: 58 | L36: 58 | M36: 4 | N36: 5 | O36: 267 | P36: 12 | Q36: 87 | R36: 7 | S36: 8 | T36: 0 | U36: 0 | V36: 0 | W36: 0 | X36: 7 | Y36: 7 | Z36: 0 | AA36: 1 | AB36: 0.90429055 | AC36: 0.15802708 | AD36: 0.16648917 | AE36: 1 | AF36: 2.638702 | AG36: 0.90257927 | AH36: 0.43030774 | AI36: -0.01363499 | AJ36: -0.43041422 | AK36: 0.90261128 | AL36: -0.0060386694 | AM36: 0.0097086097 | AN36: 0.011319071 | AO36: 0.9998888 | AP36: 22.823913 | AQ36: 6.5226121 | AR36: 1.5551182
A37: baseline | B37: svd+ransac | C37: 24 | D37: s1-s4 | E37: 0 | F37: 24_s1-s4 | G37: 0.1 | H37: sensitivity(not paper) | I37: 58 | J37: 58 | K37: 58 | L37: 58 | M37: 4 | N37: 5 | O37: 267 | P37: 12 | Q37: 87 | R37: 7 | S37: 8 | T37: 0 | U37: 0 | V37: 0 | W37: 0 | X37: 7 | Y37: 7 | Z37: 7 | AA37: 1 | AB37: 0.90429055 | AC37: 0.15802708 | AD37: 0.16648917 | AE37: 1 | AF37: 3.619577 | AG37: 0.90257927 | AH37: 0.43030774 | AI37: -0.01363499 | AJ37: -0.43041422 | AK37: 0.90261128 | AL37: -0.0060386694 | AM37: 0.0097086097 | AN37: 0.011319071 | AO37: 0.9998888 | AP37: 22.823913 | AQ37: 6.5226121 | AR37: 1.5551182
A38: baseline | B38: svd | C38: 24 | D38: s1-s5 | E38: 0 | F38: 24_s1-s5 | G38: 0.1 | H38: sensitivity(not paper) | I38: 58 | J38: 83 | K38: 58 | L38: 83 | M38: 6 | N38: 10 | O38: 395 | P38: 6 | Q38: 27 | R38: 7 | S38: 2 | T38: 1 | U38: 7 | V38: 7 | W38: 19 | X38: 7 | Y38: 7 | Z38: 0 | AA38: 1 | AB38: 0.69760513 | AC38: 0.077627163 | AD38: 0.087507863 | AE38: 1 | AF38: 4.028939 | AG38: 0.22530572 | AH38: -0.97428555 | AI38: -0.0022344652 | AJ38: 0.97419562 | AK38: 0.22531534 | AL38: -0.013262367 | AM38: 0.013424792 | AN38: 0.00081128093 | AO38: 0.99990955 | AP38: -16.511219 | AQ38: 20.510369 | AR38: 1.0719432
A39: baseline | B39: svd+ransac | C39: 24 | D39: s1-s5 | E39: 0 | F39: 24_s1-s5 | G39: 0.1 | H39: sensitivity(not paper) | I39: 58 | J39: 83 | K39: 58 | L39: 83 | M39: 6 | N39: 10 | O39: 395 | P39: 6 | Q39: 27 | R39: 7 | S39: 2 | T39: 1 | U39: 7 | V39: 7 | W39: 19 | X39: 7 | Y39: 7 | Z39: 7 | AA39: 1 | AB39: 0.69760513 | AC39: 0.077627163 | AD39: 0.087507863 | AE39: 1 | AF39: 4.756677 | AG39: 0.22530572 | AH39: -0.97428555 | AI39: -0.0022344652 | AJ39: 0.97419562 | AK39: 0.22531534 | AL39: -0.013262367 | AM39: 0.013424792 | AN39: 0.00081128093 | AO39: 0.99990955 | AP39: -16.511219 | AQ39: 20.510369 | AR39: 1.0719432
A40: baseline | B40: svd | C40: 24 | D40: s1-s6 | E40: 0 | F40: 24_s1-s6 | G40: 0.1 | H40: sensitivity(not paper) | I40: 58 | J40: 92 | K40: 58 | L40: 92 | M40: 5 | N40: 11 | O40: 393 | P40: 9 | Q40: 33 | R40: 3 | S40: 3 | T40: 1 | U40: 3 | V40: 3 | W40: 0 | X40: 0 | Y40: 0 | Z40: 0 | AA40: 0 | AE40: 0 | AF40: 3.935434 | AG40: 1 | AH40: 0 | AI40: 0 | AJ40: 0 | AK40: 1 | AL40: 0 | AM40: 0 | AN40: 0 | AO40: 1 | AP40: 0 | AQ40: 0 | AR40: 0
A41: baseline | B41: svd+ransac | C41: 24 | D41: s1-s6 | E41: 0 | F41: 24_s1-s6 | G41: 0.1 | H41: sensitivity(not paper) | I41: 58 | J41: 92 | K41: 58 | L41: 92 | M41: 5 | N41: 11 | O41: 393 | P41: 9 | Q41: 33 | R41: 3 | S41: 3 | T41: 1 | U41: 3 | V41: 3 | W41: 0 | X41: 0 | Y41: 0 | Z41: 0 | AA41: 0 | AE41: 0 | AF41: 3.93537 | AG41: 1 | AH41: 0 | AI41: 0 | AJ41: 0 | AK41: 1 | AL41: 0 | AM41: 0 | AN41: 0 | AO41: 1 | AP41: 0 | AQ41: 0 | AR41: 0
A42: baseline | B42: svd | C42: 25 | D42: s1-s2 | E42: 1 | F42: 25_s1-s2 | G42: 0.1 | H42: sensitivity(not paper) | I42: 55 | J42: 65 | K42: 55 | L42: 65 | M42: 4 | N42: 11 | O42: 363 | P42: 16 | Q42: 128 | R42: 8 | S42: 12 | T42: 0 | U42: 0 | V42: 0 | W42: 0 | X42: 13 | Y42: 13 | Z42: 0 | AA42: 1 | AB42: 0.58314024 | AC42: 0.063861059 | AD42: 0.074914097 | AE42: 1 | AF42: 2.84156 | AG42: -0.7184912 | AH42: -0.69551558 | AI42: 0.0053371233 | AJ42: 0.69544071 | AK42: -0.71849861 | AL42: -0.011043949 | AM42: 0.011515954 | AN42: -0.0042233276 | AO42: 0.99992477 | AP42: -11.090418 | AQ42: -0.86600409 | AR42: 0.60387262
A43: baseline | B43: svd+ransac | C43: 25 | D43: s1-s2 | E43: 1 | F43: 25_s1-s2 | G43: 0.1 | H43: sensitivity(not paper) | I43: 55 | J43: 65 | K43: 55 | L43: 65 | M43: 4 | N43: 11 | O43: 363 | P43: 16 | Q43: 128 | R43: 8 | S43: 12 | T43: 0 | U43: 0 | V43: 0 | W43: 0 | X43: 13 | Y43: 13 | Z43: 12 | AA43: 1 | AB43: 0.29976546 | AC43: 0.04156537 | AD43: 0.047038676 | AE43: 1 | AF43: 4.227457 | AG43: -0.71844057 | AH43: -0.69556867 | AI43: 0.0052319917 | AJ43: 0.69555363 | AK43: -0.71845953 | AL43: -0.0045875076 | AM43: 0.0069499009 | AN43: 0.00034327925 | AO43: 0.99997579 | AP43: -11.08828 | AQ43: -0.85282079 | AR43: 0.57456797
A44: baseline | B44: svd | C44: 25 | D44: s1-s3 | E44: 1 | F44: 25_s1-s3 | G44: 0.1 | H44: sensitivity(not paper) | I44: 55 | J44: 51 | K44: 55 | L44: 51 | M44: 2 | N44: 8 | O44: 232 | P44: 9 | Q44: 133 | R44: 23 | S44: 11 | T44: 0 | U44: 0 | V44: 0 | W44: 0 | X44: 7 | Y44: 7 | Z44: 0 | AA44: 1 | AB44: 1.0253997 | AC44: 0.078596199 | AD44: 0.097796549 | AE44: 1 | AF44: 2.269927 | AG44: 0.93453383 | AH44: 0.35559166 | AI44: -0.014180493 | AJ44: -0.35551809 | AK44: 0.93463935 | AL44: 0.0074948626 | AM44: 0.015918757 | AN44: -0.0019627809 | AO44: 0.99987136 | AP44: 8.3767167 | AQ44: 1.3891505 | AR44: 0.73379515
A45: baseline | B45: svd+ransac | C45: 25 | D45: s1-s3 | E45: 1 | F45: 25_s1-s3 | G45: 0.1 | H45: sensitivity(not paper) | I45: 55 | J45: 51 | K45: 55 | L45: 51 | M45: 2 | N45: 8 | O45: 232 | P45: 9 | Q45: 133 | R45: 23 | S45: 11 | T45: 0 | U45: 0 | V45: 0 | W45: 0 | X45: 7 | Y45: 7 | Z45: 6 | AA45: 1 | AB45: 0.33636211 | AC45: 0.019241075 | AD45: 0.028328585 | AE45: 1 | AF45: 3.119667 | AG45: 0.93427408 | AH45: 0.35653331 | AI45: -0.00399329 | AJ45: -0.35653158 | AK45: 0.93428255 | AL45: 0.0011622272 | AM45: 0.0041452339 | AN45: 0.00033789521 | AO45: 0.99999135 | AP45: 8.4041451 | AQ45: 1.3654749 | AR45: 0.68509434
A46: baseline | B46: svd | C46: 25 | D46: s1-s4 | E46: 0 | F46: 25_s1-s4 | G46: 0.1 | H46: sensitivity(not paper) | I46: 55 | J46: 49 | K46: 55 | L46: 49 | M46: 2 | N46: 6 | O46: 215 | P46: 8 | Q46: 91 | R46: 11 | S46: 8 | T46: 0 | U46: 0 | V46: 0 | W46: 0 | X46: 6 | Y46: 6 | Z46: 0 | AA46: 1 | AB46: 0.97587083 | AC46: 0.16930534 | AD46: 0.17936597 | AE46: 1 | AF46: 1.90999 | AG46: 0.90234511 | AH46: 0.43075052 | AI46: -0.015076386 | AJ46: -0.43086946 | AK46: 0.90239659 | AL46: -0.0056477794 | AM46: 0.011172096 | AN46: 0.011592201 | AO46: 0.99987039 | AP46: 22.850066 | AQ46: 6.517812 | AR46: 1.5744688
A47: baseline | B47: svd+ransac | C47: 25 | D47: s1-s4 | E47: 0 | F47: 25_s1-s4 | G47: 0.1 | H47: sensitivity(not paper) | I47: 55 | J47: 49 | K47: 55 | L47: 49 | M47: 2 | N47: 6 | O47: 215 | P47: 8 | Q47: 91 | R47: 11 | S47: 8 | T47: 0 | U47: 0 | V47: 0 | W47: 0 | X47: 6 | Y47: 6 | Z47: 6 | AA47: 1 | AB47: 0.97587083 | AC47: 0.16930534 | AD47: 0.17936597 | AE47: 1 | AF47: 4.022284 | AG47: 0.90234511 | AH47: 0.43075052 | AI47: -0.015076386 | AJ47: -0.43086946 | AK47: 0.90239659 | AL47: -0.0056477794 | AM47: 0.011172096 | AN47: 0.011592201 | AO47: 0.99987039 | AP47: 22.850066 | AQ47: 6.517812 | AR47: 1.5744688
A48: baseline | B48: svd | C48: 25 | D48: s1-s5 | E48: 0 | F48: 25_s1-s5 | G48: 0.1 | H48: sensitivity(not paper) | I48: 55 | J48: 79 | K48: 55 | L48: 79 | M48: 5 | N48: 16 | O48: 368 | P48: 8 | Q48: 68 | R48: 8 | S48: 6 | T48: 0 | U48: 0 | V48: 0 | W48: 0 | X48: 3 | Y48: 3 | Z48: 0 | AA48: 1 | AB48: 0.82073889 | AC48: 0.22777262 | AD48: 0.23446144 | AE48: 1 | AF48: 3.295574 | AG48: 0.22913492 | AH48: -0.97332609 | AI48: -0.011554586 | AJ48: 0.97339385 | AK48: 0.22910316 | AL48: 0.0040192853 | AM48: -0.001264883 | AN48: -0.012168122 | AO48: 0.99992517 | AP48: -16.485683 | AQ48: 20.619609 | AR48: 0.78805732
A49: baseline | B49: svd+ransac | C49: 25 | D49: s1-s5 | E49: 0 | F49: 25_s1-s5 | G49: 0.1 | H49: sensitivity(not paper) | I49: 55 | J49: 79 | K49: 55 | L49: 79 | M49: 5 | N49: 16 | O49: 368 | P49: 8 | Q49: 68 | R49: 8 | S49: 6 | T49: 0 | U49: 0 | V49: 0 | W49: 0 | X49: 3 | Y49: 3 | Z49: 3 | AA49: 1 | AB49: 0.82073889 | AC49: 0.22777262 | AD49: 0.23446144 | AE49: 1 | AF49: 3.570587 | AG49: 0.22913492 | AH49: -0.97332609 | AI49: -0.011554586 | AJ49: 0.97339385 | AK49: 0.22910316 | AL49: 0.0040192853 | AM49: -0.001264883 | AN49: -0.012168122 | AO49: 0.99992517 | AP49: -16.485683 | AQ49: 20.619609 | AR49: 0.78805732
A50: baseline | B50: svd | C50: 25 | D50: s1-s6 | E50: 0 | F50: 25_s1-s6 | G50: 0.1 | H50: sensitivity(not paper) | I50: 55 | J50: 84 | K50: 55 | L50: 84 | M50: 6 | N50: 10 | O50: 346 | P50: 5 | Q50: 28 | R50: 8 | S50: 2 | T50: 1 | U50: 8 | V50: 8 | W50: 39 | X50: 8 | Y50: 8 | Z50: 0 | AA50: 1 | AB50: 1.0823551 | AC50: 0.10789361 | AD50: 0.12766592 | AE50: 1 | AF50: 3.897009 | AG50: 0.98895925 | AH50: 0.14732898 | AI50: -0.015930111 | AJ50: -0.14724344 | AK50: 0.98907943 | AL50: 0.0064218635 | AM50: 0.016702272 | AN50: -0.0040053569 | AO50: 0.99985248 | AP50: 25.147462 | AQ50: 19.821548 | AR50: 2.1953232
A51: baseline | B51: svd+ransac | C51: 25 | D51: s1-s6 | E51: 0 | F51: 25_s1-s6 | G51: 0.1 | H51: sensitivity(not paper) | I51: 55 | J51: 84 | K51: 55 | L51: 84 | M51: 6 | N51: 10 | O51: 346 | P51: 5 | Q51: 28 | R51: 8 | S51: 2 | T51: 1 | U51: 8 | V51: 8 | W51: 39 | X51: 8 | Y51: 8 | Z51: 8 | AA51: 1 | AB51: 1.0823551 | AC51: 0.10789361 | AD51: 0.12766592 | AE51: 1 | AF51: 4.768234 | AG51: 0.98895925 | AH51: 0.14732898 | AI51: -0.015930111 | AJ51: -0.14724344 | AK51: 0.98907943 | AL51: 0.0064218635 | AM51: 0.016702272 | AN51: -0.0040053569 | AO51: 0.99985248 | AP51: 25.147462 | AQ51: 19.821548 | AR51: 2.1953232
...

Sheet 新估計變換
A1: method | B1: solver | C1: seed | D1: pair | E1: transform_ok | F1: r00 | G1: r01 | H1: r02 | I1: r10 | J1: r11 | K1: r12 | L1: r20 | M1: r21 | N1: r22 | O1: t0 | P1: t1 | Q1: t2
A2: baseline | B2: svd | C2: 21 | D2: s1-s2 | E2: 1 | F2: -0.71875906 | G2: -0.69524307 | H2: 0.0047421651 | I2: 0.69524829 | J2: -0.7187693 | K2: -0.00071185772 | L2: 0.0039034368 | M2: 0.002785328 | N2: 0.9999885 | O2: -11.076481 | P2: -0.87976367 | Q2: 0.58003899
A3: baseline | B3: svd+ransac | C3: 21 | D3: s1-s2 | E3: 1 | F3: -0.71875906 | G3: -0.69524307 | H3: 0.0047421651 | I3: 0.69524829 | J3: -0.7187693 | K3: -0.00071185772 | L3: 0.0039034368 | M3: 0.002785328 | N3: 0.9999885 | O3: -11.076481 | P3: -0.87976367 | Q3: 0.58003899
A4: baseline | B4: svd | C4: 21 | D4: s1-s3 | E4: 1 | F4: 0.9338585 | G4: 0.35756912 | H4: -0.0072545448 | I4: -0.35753125 | J4: 0.93388176 | K4: 0.0060209877 | L4: 0.0089278063 | M4: -0.0030290241 | N4: 0.99995556 | O4: 8.3919229 | P4: 1.3841447 | Q4: 0.68182258
A5: baseline | B5: svd+ransac | C5: 21 | D5: s1-s3 | E5: 1 | F5: 0.9338585 | G5: 0.35756912 | H5: -0.0072545448 | I5: -0.35753125 | J5: 0.93388176 | K5: 0.0060209877 | L5: 0.0089278063 | M5: -0.0030290241 | N5: 0.99995556 | O5: 8.3919229 | P5: 1.3841447 | Q5: 0.68182258
A6: baseline | B6: svd | C6: 21 | D6: s1-s4 | E6: 1 | F6: 0.90222477 | G6: 0.43101311 | H6: -0.014770273 | I6: -0.43113321 | J6: 0.9022678 | K6: -0.0060802343 | L6: 0.010706081 | M6: 0.011853693 | N6: 0.99987243 | O6: 22.837754 | P6: 6.5281208 | Q6: 1.5680333
A7: baseline | B7: svd+ransac | C7: 21 | D7: s1-s4 | E7: 1 | F7: 0.90222477 | G7: 0.43101311 | H7: -0.014770273 | I7: -0.43113321 | J7: 0.9022678 | K7: -0.0060802343 | L7: 0.010706081 | M7: 0.011853693 | N7: 0.99987243 | O7: 22.837754 | P7: 6.5281208 | Q7: 1.5680333
A8: baseline | B8: svd | C8: 21 | D8: s1-s5 | E8: 1 | F8: 0.22466187 | G8: -0.97440097 | H8: -0.008354243 | I8: 0.97440311 | J8: 0.22471712 | K8: -0.0063865856 | L8: 0.0081004367 | M8: -0.0067055781 | N8: 0.99994471 | O8: -16.502891 | P8: 20.505421 | Q8: 0.88708549
A9: baseline | B9: svd+ransac | C9: 21 | D9: s1-s5 | E9: 1 | F9: 0.22466187 | G9: -0.97440097 | H9: -0.008354243 | I9: 0.97440311 | J9: 0.22471712 | K9: -0.0063865856 | L9: 0.0081004367 | M9: -0.0067055781 | N9: 0.99994471 | O9: -16.502891 | P9: 20.505421 | Q9: 0.88708549
A10: baseline | B10: svd | C10: 21 | D10: s1-s6 | E10: 1 | F10: 0.98862944 | G10: 0.14870962 | H10: -0.022299661 | I10: -0.14848264 | J10: 0.98884791 | K10: 0.011520011 | L10: 0.02376411 | M10: -0.0080779099 | N10: 0.99968496 | O10: 25.100199 | P10: 19.821357 | Q10: 2.2748919
A11: baseline | B11: svd+ransac | C11: 21 | D11: s1-s6 | E11: 1 | F11: 0.98862944 | G11: 0.14870962 | H11: -0.022299661 | I11: -0.14848264 | J11: 0.98884791 | K11: 0.011520011 | L11: 0.02376411 | M11: -0.0080779099 | N11: 0.99968496 | O11: 25.100199 | P11: 19.821357 | Q11: 2.2748919
A12: baseline | B12: svd | C12: 22 | D12: s1-s2 | E12: 1 | F12: -0.71707853 | G12: -0.69698166 | H12: -0.0038672388 | I12: 0.69698886 | J12: -0.7170462 | K12: -0.007161253 | L12: 0.0022182731 | M12: -0.0078306031 | N12: 0.99996688 | O12: -11.126673 | P12: -0.85474771 | Q12: 0.42810177
A13: baseline | B13: svd+ransac | C13: 22 | D13: s1-s2 | E13: 1 | F13: -0.71707853 | G13: -0.69698166 | H13: -0.0038672388 | I13: 0.69698886 | J13: -0.7170462 | K13: -0.007161253 | L13: 0.0022182731 | M13: -0.0078306031 | N13: 0.99996688 | O13: -11.126673 | P13: -0.85474771 | Q13: 0.42810177
... A25: baseline | B25: svd+ransac | C25: 23 | D25: s1-s3 | E25: 1 | F25: 0.93402941 | G25: 0.35706791 | H25: -0.0095687414 | I25: -0.35698699 | J25: 0.93406412 | K25: 0.0091931448 | L25: 0.012220395 | M25: -0.0051707514 | N25: 0.99991196 | O25: 8.3792432 | P25: 1.3722301 | Q25: 0.67699776
A26: baseline | B26: svd | C26: 23 | D26: s1-s4 | E26: 0
A27: baseline | B27: svd+ransac | C27: 23 | D27: s1-s4 | E27: 0
A28: baseline | B28: svd | C28: 23 | D28: s1-s5 | E28: 1 | F28: 0.22545292 | G28: -0.97425396 | H28: 0.000438209 | I28: 0.97423269 | J28: 0.22544497 | K28: -0.0067259834 | L28: 0.006454024 | M28: 0.0019433101 | N28: 0.99997728 | O28: -16.520908 | P28: 20.516821 | Q28: 1.0656625
A29: baseline | B29: svd+ransac | C29: 23 | D29: s1-s5 | E29: 1 | F29: 0.22545292 | G29: -0.97425396 | H29: 0.000438209 | I29: 0.97423269 | J29: 0.22544497 | K29: -0.0067259834 | L29: 0.006454024 | M29: 0.0019433101 | N29: 0.99997728 | O29: -16.520908 | P29: 20.516821 | Q29: 1.0656625
A30: baseline | B30: svd | C30: 23 | D30: s1-s6 | E30: 1 | F30: 0.98908189 | G30: 0.14639676 | H30: -0.016881772 | I30: -0.14629675 | J30: 0.98921583 | K30: 0.0070208043 | L30: 0.01772754 | M30: -0.004474402 | N30: 0.99983284 | O30: 25.126614 | P30: 19.808271 | Q30: 2.1951162
A31: baseline | B31: svd+ransac | C31: 23 | D31: s1-s6 | E31: 1 | F31: 0.98908189 | G31: 0.14639676 | H31: -0.016881772 | I31: -0.14629675 | J31: 0.98921583 | K31: 0.0070208043 | L31: 0.01772754 | M31: -0.004474402 | N31: 0.99983284 | O31: 25.126614 | P31: 19.808271 | Q31: 2.1951162
A32: baseline | B32: svd | C32: 24 | D32: s1-s2 | E32: 1 | F32: -0.71838867 | G32: -0.69562216 | H32: 0.005247119 | I32: 0.69559609 | J32: -0.71840748 | K32: -0.0060631833 | L32: 0.0079872542 | M32: -0.00070584666 | N32: 0.99996785 | O32: -11.068632 | P32: -0.87514759 | Q32: 0.58214066
A33: baseline | B33: svd+ransac | C33: 24 | D33: s1-s2 | E33: 1 | F33: -0.71838867 | G33: -0.69562216 | H33: 0.005247119 | I33: 0.69559609 | J33: -0.71840748 | K33: -0.0060631833 | L33: 0.0079872542 | M33: -0.00070584666 | N33: 0.99996785 | O33: -11.068632 | P33: -0.87514759 | Q33: 0.58214066
A34: baseline | B34: svd | C34: 24 | D34: s1-s3 | E34: 1 | F34: 0.9344044 | G34: 0.35619061 | H34: -0.0040822401 | I34: -0.35617292 | J34: 0.93440933 | K34: 0.0044793197 | L34: 0.0054099748 | M34: -0.0027315126 | N34: 0.99998164 | O34: 8.3822563 | P34: 1.3957996 | Q34: 0.64272871
A35: baseline | B35: svd+ransac | C35: 24 | D35: s1-s3 | E35: 1 | F35: 0.9344044 | G35: 0.35619061 | H35: -0.0040822401 | I35: -0.35617292 | J35: 0.93440933 | K35: 0.0044793197 | L35: 0.0054099748 | M35: -0.0027315126 | N35: 0.99998164 | O35: 8.3822563 | P35: 1.3957996 | Q35: 0.64272871
A36: baseline | B36: svd | C36: 24 | D36: s1-s4 | E36: 1 | F36: 0.90257927 | G36: 0.43030774 | H36: -0.01363499 | I36: -0.43041422 | J36: 0.90261128 | K36: -0.0060386694 | L36: 0.0097086097 | M36: 0.011319071 | N36: 0.9998888 | O36: 22.823913 | P36: 6.5226121 | Q36: 1.5551182
A37: baseline | B37: svd+ransac | C37: 24 | D37: s1-s4 | E37: 1 | F37: 0.90257927 | G37: 0.43030774 | H37: -0.01363499 | I37: -0.43041422 | J37: 0.90261128 | K37: -0.0060386694 | L37: 0.0097086097 | M37: 0.011319071 | N37: 0.9998888 | O37: 22.823913 | P37: 6.5226121 | Q37: 1.5551182
A38: baseline | B38: svd | C38: 24 | D38: s1-s5 | E38: 1 | F38: 0.22530572 | G38: -0.97428555 | H38: -0.0022344652 | I38: 0.97419562 | J38: 0.22531534 | K38: -0.013262367 | L38: 0.013424792 | M38: 0.00081128093 | N38: 0.99990955 | O38: -16.511219 | P38: 20.510369 | Q38: 1.0719432
A39: baseline | B39: svd+ransac | C39: 24 | D39: s1-s5 | E39: 1 | F39: 0.22530572 | G39: -0.97428555 | H39: -0.0022344652 | I39: 0.97419562 | J39: 0.22531534 | K39: -0.013262367 | L39: 0.013424792 | M39: 0.00081128093 | N39: 0.99990955 | O39: -16.511219 | P39: 20.510369 | Q39: 1.0719432
A40: baseline | B40: svd | C40: 24 | D40: s1-s6 | E40: 0
A41: baseline | B41: svd+ransac | C41: 24 | D41: s1-s6 | E41: 0
A42: baseline | B42: svd | C42: 25 | D42: s1-s2 | E42: 1 | F42: -0.7184912 | G42: -0.69551558 | H42: 0.0053371233 | I42: 0.69544071 | J42: -0.71849861 | K42: -0.011043949 | L42: 0.011515954 | M42: -0.0042233276 | N42: 0.99992477 | O42: -11.090418 | P42: -0.86600409 | Q42: 0.60387262
A43: baseline | B43: svd+ransac | C43: 25 | D43: s1-s2 | E43: 1 | F43: -0.71844057 | G43: -0.69556867 | H43: 0.0052319917 | I43: 0.69555363 | J43: -0.71845953 | K43: -0.0045875076 | L43: 0.0069499009 | M43: 0.00034327925 | N43: 0.99997579 | O43: -11.08828 | P43: -0.85282079 | Q43: 0.57456797
A44: baseline | B44: svd | C44: 25 | D44: s1-s3 | E44: 1 | F44: 0.93453383 | G44: 0.35559166 | H44: -0.014180493 | I44: -0.35551809 | J44: 0.93463935 | K44: 0.0074948626 | L44: 0.015918757 | M44: -0.0019627809 | N44: 0.99987136 | O44: 8.3767167 | P44: 1.3891505 | Q44: 0.73379515
A45: baseline | B45: svd+ransac | C45: 25 | D45: s1-s3 | E45: 1 | F45: 0.93427408 | G45: 0.35653331 | H45: -0.00399329 | I45: -0.35653158 | J45: 0.93428255 | K45: 0.0011622272 | L45: 0.0041452339 | M45: 0.00033789521 | N45: 0.99999135 | O45: 8.4041451 | P45: 1.3654749 | Q45: 0.68509434
A46: baseline | B46: svd | C46: 25 | D46: s1-s4 | E46: 1 | F46: 0.90234511 | G46: 0.43075052 | H46: -0.015076386 | I46: -0.43086946 | J46: 0.90239659 | K46: -0.0056477794 | L46: 0.011172096 | M46: 0.011592201 | N46: 0.99987039 | O46: 22.850066 | P46: 6.517812 | Q46: 1.5744688
A47: baseline | B47: svd+ransac | C47: 25 | D47: s1-s4 | E47: 1 | F47: 0.90234511 | G47: 0.43075052 | H47: -0.015076386 | I47: -0.43086946 | J47: 0.90239659 | K47: -0.0056477794 | L47: 0.011172096 | M47: 0.011592201 | N47: 0.99987039 | O47: 22.850066 | P47: 6.517812 | Q47: 1.5744688
A48: baseline | B48: svd | C48: 25 | D48: s1-s5 | E48: 1 | F48: 0.22913492 | G48: -0.97332609 | H48: -0.011554586 | I48: 0.97339385 | J48: 0.22910316 | K48: 0.0040192853 | L48: -0.001264883 | M48: -0.012168122 | N48: 0.99992517 | O48: -16.485683 | P48: 20.619609 | Q48: 0.78805732
A49: baseline | B49: svd+ransac | C49: 25 | D49: s1-s5 | E49: 1 | F49: 0.22913492 | G49: -0.97332609 | H49: -0.011554586 | I49: 0.97339385 | J49: 0.22910316 | K49: 0.0040192853 | L49: -0.001264883 | M49: -0.012168122 | N49: 0.99992517 | O49: -16.485683 | P49: 20.619609 | Q49: 0.78805732
A50: baseline | B50: svd | C50: 25 | D50: s1-s6 | E50: 1 | F50: 0.98895925 | G50: 0.14732898 | H50: -0.015930111 | I50: -0.14724344 | J50: 0.98907943 | K50: 0.0064218635 | L50: 0.016702272 | M50: -0.0040053569 | N50: 0.99985248 | O50: 25.147462 | P50: 19.821548 | Q50: 2.1953232
A51: baseline | B51: svd+ransac | C51: 25 | D51: s1-s6 | E51: 1 | F51: 0.98895925 | G51: 0.14732898 | H51: -0.015930111 | I51: -0.14724344 | J51: 0.98907943 | K51: 0.0064218635 | L51: 0.016702272 | M51: -0.0040053569 | N51: 0.99985248 | O51: 25.147462 | P51: 19.821548 | Q51: 2.1953232
...

Sheet 新每seed
A1: 方法 | B1: solver | C1: seed | D1: 案例數 | E1: 成功數 | F1: 成功率
A2: baseline | B2: svd | C2: 21 | D2: 15 | E2: 14 | F2: 0.93333333
A3: baseline | B3: svd | C3: 22 | D3: 15 | E3: 15 | F3: 1
A4: baseline | B4: svd | C4: 23 | D4: 15 | E4: 12 | F4: 0.8
A5: baseline | B5: svd | C5: 24 | D5: 15 | E5: 14 | F5: 0.93333333
A6: baseline | B6: svd | C6: 25 | D6: 15 | E6: 14 | F6: 0.93333333
A7: baseline | B7: svd | C7: 26 | D7: 15 | E7: 13 | F7: 0.86666667
A8: baseline | B8: svd | C8: 27 | D8: 15 | E8: 15 | F8: 1
A9: baseline | B9: svd | C9: 28 | D9: 15 | E9: 14 | F9: 0.93333333
A10: baseline | B10: svd | C10: 29 | D10: 15 | E10: 14 | F10: 0.93333333
A11: baseline | B11: svd | C11: 30 | D11: 15 | E11: 14 | F11: 0.93333333
A12: baseline | B12: svd+ransac | C12: 21 | D12: 15 | E12: 15 | F12: 1
A13: baseline | B13: svd+ransac | C13: 22 | D13: 15 | E13: 15 | F13: 1
... A41: recovery | B41: svd+ransac | C41: 30 | D41: 15 | E41: 15 | F41: 1

Sheet 新各配對
A1: 方法 | B1: solver | C1: pair | D1: 官方列表 | E1: 案例數 | F1: 成功數 | G1: 成功率
A2: baseline | B2: svd | C2: s1-s2 | D2: 1 | E2: 10 | F2: 10 | G2: 1
A3: baseline | B3: svd | C3: s1-s3 | D3: 1 | E3: 10 | F3: 10 | G3: 1
A4: baseline | B4: svd | C4: s1-s4 | D4: 0 | E4: 10 | F4: 9 | G4: 0.9
A5: baseline | B5: svd | C5: s1-s5 | D5: 0 | E5: 10 | F5: 8 | G5: 0.8
A6: baseline | B6: svd | C6: s1-s6 | D6: 0 | E6: 10 | F6: 7 | G6: 0.7
A7: baseline | B7: svd | C7: s2-s3 | D7: 1 | E7: 10 | F7: 8 | G7: 0.8
A8: baseline | B8: svd | C8: s2-s4 | D8: 1 | E8: 10 | F8: 10 | G8: 1
A9: baseline | B9: svd | C9: s2-s5 | D9: 1 | E9: 10 | F9: 9 | G9: 0.9
A10: baseline | B10: svd | C10: s2-s6 | D10: 0 | E10: 10 | F10: 9 | G10: 0.9
A11: baseline | B11: svd | C11: s3-s4 | D11: 1 | E11: 10 | F11: 10 | G11: 1
A12: baseline | B12: svd | C12: s3-s5 | D12: 1 | E12: 10 | F12: 10 | G12: 1
A13: baseline | B13: svd | C13: s3-s6 | D13: 0 | E13: 10 | F13: 10 | G13: 1
... A61: recovery | B61: svd+ransac | C61: s5-s6 | D61: 1 | E61: 10 | F61: 10 | G61: 1

Sheet 新配對比較
A1: 項目 | B1: 值
A2: primary_solver | B2: svd+ransac
A3: rescued_cases | B3: [{"seed": 23, "pair": "s1-s4"}, {"seed": 24, "pair": "s1-s6"}, {"seed": 26, "pair": "s1-s5"}, {"seed": 26, "pair": "s1-s6"}, {"seed": 28, "pair": "s1-s5"}, {"seed": 30, "pair": "s1-s6"}, {"seed": 29, "pair": "s2-s5"}, {"seed": 23, "pair": "s4-s5"}]
A4: regressed_cases | B4: []
A5: seed_gains | B5: [0, 0, 2, 1, 0, 2, 0, 1, 1, 1]
A6: winning_seeds | B6: 6
A7: losing_seeds | B7: 0
A8: tied_seeds | B8: 4
A9: paired_seed_sign_p | B9: 0.03125
A10: common_success_cases | B10: 142
A11: common_ep_baseline_m | B11: 0.067380268
A12: common_ep_recovery_m | B12: 0.061943082
A13: interpretation | B13: one prespecified frozen primary comparison; seeds repeat the same forest, not independent forests

Sheet 舊seed候選摘要
A1: method | B1: cases | C1: success | D1: official_cases | E1: official_success | F1: recovery_triggered | G1: recovery_adopted
A2: baseline | B2: 150 | C2: 142 | D2: 100 | E2: 99 | F2: 0 | G2: 0
A3: triangle_scarce | B3: 150 | C3: 149 | D3: 100 | E3: 100 | F3: 7 | G3: 7
A4: evidence_scarce | B4: 150 | C4: 149 | D4: 100 | E4: 100 | F4: 7 | G4: 7
A5: evidence_weak | B5: 150 | C5: 150 | D5: 100 | E5: 100 | F5: 31 | G5: 31

Sheet 舊seed候選逐次
A1: method | B1: seed | C1: pair | D1: label | E1: threshold | F1: setting | G1: solver | H1: n_src_kp | I1: n_tgt_kp | J1: descriptors_src | K1: descriptors_tgt | L1: d12_enc2_s0_is_p1 | M1: d12_enc3_s0_is_p1p2 | N1: gate_passed | O1: candidates | P1: best_score | Q1: best_dc | R1: best_fm | S1: used_triangle | T1: tri_set_src | U1: tri_set_tgt | V1: tri_matches | W1: n_matches | X1: n_correct_matches | Y1: ransac_inliers | Z1: transform_ok | AA1: rot_err_deg | AB1: trans_err_m | AC1: e_p_m | AD1: success | AE1: time_ms | AF1: r00 | AG1: r01 | AH1: r02 | AI1: r10 | AJ1: r11 | AK1: r12 | AL1: r20 | AM1: r21 | AN1: r22 | AO1: t0 | AP1: t1 | AQ1: t2 | AR1: recovery | AS1: recovery_triggered | AT1: recovery_accepted | AU1: recovery_hypotheses | AV1: recovery_support | AW1: recovery_median_m
A2: baseline | B2: 11 | C2: s1-s2 | D2: 11_s1-s2 | E2: 0.1 | F2: sensitivity(not paper) | G2: svd | H2: 55 | I2: 57 | J2: 55 | K2: 57 | L2: 5 | M2: 12 | N2: 363 | O2: 13 | P2: 175 | Q2: 35 | R2: 14 | S2: 0 | T2: 0 | U2: 0 | V2: 0 | W2: 10 | X2: 10 | Y2: 0 | Z2: 1 | AA2: 0.25001646 | AB2: 0.025693373 | AD2: 1 | AE2: 1.927619 | AF2: -0.71811621 | AG2: -0.69590536 | AH2: 0.0049833538 | AI2: 0.69590767 | AJ2: -0.71812962 | AK2: -0.0015402371 | AL2: 0.0046505532 | AM2: 0.0023618849 | AN2: 0.9999864 | AO2: -11.085077 | AP2: -0.86552333 | AQ2: 0.55876872
A3: baseline | B3: 11 | C3: s1-s2 | D3: 11_s1-s2 | E3: 0.1 | F3: sensitivity(not paper) | G3: svd+ransac | H3: 55 | I3: 57 | J3: 55 | K3: 57 | L3: 5 | M3: 12 | N3: 363 | O3: 13 | P3: 175 | Q3: 35 | R3: 14 | S3: 0 | T3: 0 | U3: 0 | V3: 0 | W3: 10 | X3: 10 | Y3: 10 | Z3: 1 | AA3: 0.25001646 | AB3: 0.025693373 | AD3: 1 | AE3: 2.718209 | AF3: -0.71811621 | AG3: -0.69590536 | AH3: 0.0049833538 | AI3: 0.69590767 | AJ3: -0.71812962 | AK3: -0.0015402371 | AL3: 0.0046505532 | AM3: 0.0023618849 | AN3: 0.9999864 | AO3: -11.085077 | AP3: -0.86552333 | AQ3: 0.55876872
A4: baseline | B4: 11 | C4: s1-s3 | D4: 11_s1-s3 | E4: 0.1 | F4: sensitivity(not paper) | G4: svd | H4: 55 | I4: 51 | J4: 55 | K4: 51 | L4: 4 | M4: 8 | N4: 267 | O4: 14 | P4: 200 | Q4: 20 | R4: 18 | S4: 0 | T4: 0 | U4: 0 | V4: 0 | W4: 12 | X4: 12 | Y4: 0 | Z4: 1 | AA4: 1.0524575 | AB4: 0.14933153 | AD4: 1 | AE4: 2.03568 | AF4: 0.93404964 | AG4: 0.35676078 | AH4: -0.016523083 | AI4: -0.35675516 | AJ4: 0.93419178 | AK4: 0.0033867801 | AL4: 0.016643999 | AM4: 0.0027312745 | AN4: 0.99985775 | AO4: 8.3527197 | AP4: 1.3792601 | AQ4: 0.80416273
A5: baseline | B5: 11 | C5: s1-s3 | D5: 11_s1-s3 | E5: 0.1 | F5: sensitivity(not paper) | G5: svd+ransac | H5: 55 | I5: 51 | J5: 55 | K5: 51 | L5: 4 | M5: 8 | N5: 267 | O5: 14 | P5: 200 | Q5: 20 | R5: 18 | S5: 0 | T5: 0 | U5: 0 | V5: 0 | W5: 12 | X5: 12 | Y5: 11 | Z5: 1 | AA5: 0.56466048 | AB5: 0.0282986 | AD5: 1 | AE5: 3.007502 | AF5: 0.93395984 | AG5: 0.35733331 | AH5: -0.0056497793 | AI5: -0.35730405 | AJ5: 0.93397149 | AK5: 0.0055734355 | AL5: 0.0072683069 | AM5: -0.0031866759 | AN5: 0.99996851 | AO5: 8.3872401 | AP5: 1.3740482 | AQ5: 0.66740337
A6: baseline | B6: 11 | C6: s1-s4 | D6: 11_s1-s4 | E6: 0.1 | F6: sensitivity(not paper) | G6: svd | H6: 55 | I6: 54 | J6: 55 | K6: 54 | L6: 3 | M6: 10 | N6: 240 | O6: 11 | P6: 125 | Q6: 15 | R6: 11 | S6: 0 | T6: 0 | U6: 0 | V6: 0 | W6: 8 | X6: 8 | Y6: 0 | Z6: 1 | AA6: 0.91136047 | AB6: 0.16312394 | AD6: 1 | AE6: 1.632852 | AF6: 0.90276828 | AG6: 0.42991163 | AH6: -0.013616914 | AI6: -0.43002114 | AJ6: 0.90279631 | AK6: -0.0063748971 | AL6: 0.0095526575 | AM6: 0.011610616 | AN6: 0.99988696 | AO6: 22.81579 | AP6: 6.5344935 | AQ6: 1.5566146
A7: baseline | B7: 11 | C7: s1-s4 | D7: 11_s1-s4 | E7: 0.1 | F7: sensitivity(not paper) | G7: svd+ransac | H7: 55 | I7: 54 | J7: 55 | K7: 54 | L7: 3 | M7: 10 | N7: 240 | O7: 11 | P7: 125 | Q7: 15 | R7: 11 | S7: 0 | T7: 0 | U7: 0 | V7: 0 | W7: 8 | X7: 8 | Y7: 8 | Z7: 1 | AA7: 0.91136047 | AB7: 0.16312394 | AD7: 1 | AE7: 2.641964 | AF7: 0.90276828 | AG7: 0.42991163 | AH7: -0.013616914 | AI7: -0.43002114 | AJ7: 0.90279631 | AK7: -0.0063748971 | AL7: 0.0095526575 | AM7: 0.011610616 | AN7: 0.99988696 | AO7: 22.81579 | AP7: 6.5344935 | AQ7: 1.5566146
A8: baseline | B8: 11 | C8: s1-s5 | D8: 11_s1-s5 | E8: 0.1 | F8: sensitivity(not paper) | G8: svd | H8: 55 | I8: 83 | J8: 55 | K8: 83 | L8: 8 | M8: 19 | N8: 490 | O8: 18 | P8: 126 | Q8: 16 | R8: 11 | S8: 0 | T8: 0 | U8: 0 | V8: 0 | W8: 9 | X8: 9 | Y8: 0 | Z8: 1 | AA8: 1.6161744 | AB8: 0.40145106 | AD8: 1 | AE8: 2.905589 | AF8: 0.22330175 | AG8: -0.97468954 | AH8: 0.010799299 | AI8: 0.97443135 | AJ8: 0.22293221 | AK8: -0.028013871 | AL8: 0.024897316 | AM8: 0.016778722 | AN8: 0.9995492 | AO8: -16.524197 | AP8: 20.415529 | AQ8: 1.3816366
A9: baseline | B9: 11 | C9: s1-s5 | D9: 11_s1-s5 | E9: 0.1 | F9: sensitivity(not paper) | G9: svd+ransac | H9: 55 | I9: 83 | J9: 55 | K9: 83 | L9: 8 | M9: 19 | N9: 490 | O9: 18 | P9: 126 | Q9: 16 | R9: 11 | S9: 0 | T9: 0 | U9: 0 | V9: 0 | W9: 9 | X9: 9 | Y9: 8 | Z9: 1 | AA9: 1.0990629 | AB9: 0.26644599 | AD9: 1 | AE9: 3.513626 | AF9: 0.22399484 | AG9: -0.97457041 | AH9: 0.0062320167 | AI9: 0.9744218 | AJ9: 0.22383261 | AK9: -0.020027757 | AL9: 0.01812353 | AM9: 0.010558727 | AN9: 0.99978 | AO9: -16.520161 | AP9: 20.450215 | AQ9: 1.2508649
A10: baseline | B10: 11 | C10: s1-s6 | D10: 11_s1-s6 | E10: 0.1 | F10: sensitivity(not paper) | G10: svd | H10: 55 | I10: 80 | J10: 55 | K10: 80 | L10: 5 | M10: 10 | N10: 374 | O10: 9 | P10: 59 | Q10: 9 | R10: 5 | S10: 0 | T10: 0 | U10: 0 | V10: 0 | W10: 5 | X10: 5 | Y10: 0 | Z10: 1 | AA10: 3.6483182 | AB10: 1.1491703 | AD10: 0 | AE10: 2.532093 | AF10: 0.98832112 | AG10: 0.13925836 | AH10: -0.06187464 | AI10: -0.13975925 | AJ10: 0.99017814 | AK10: -0.0038211502 | AL10: 0.060734789 | AM10: 0.012424077 | AN10: 0.99807661 | AO10: 24.815825 | AP10: 19.956719 | AQ10: 3.1758339
A11: baseline | B11: 11 | C11: s1-s6 | D11: 11_s1-s6 | E11: 0.1 | F11: sensitivity(not paper) | G11: svd+ransac | H11: 55 | I11: 80 | J11: 55 | K11: 80 | L11: 5 | M11: 10 | N11: 374 | O11: 9 | P11: 59 | Q11: 9 | R11: 5 | S11: 0 | T11: 0 | U11: 0 | V11: 0 | W11: 5 | X11: 5 | Y11: 5 | Z11: 1 | AA11: 3.6483182 | AB11: 1.1491703 | AD11: 0 | AE11: 2.926866 | AF11: 0.98832112 | AG11: 0.13925836 | AH11: -0.06187464 | AI11: -0.13975925 | AJ11: 0.99017814 | AK11: -0.0038211502 | AL11: 0.060734789 | AM11: 0.012424077 | AN11: 0.99807661 | AO11: 24.815825 | AP11: 19.956719 | AQ11: 3.1758339
A12: baseline | B12: 11 | C12: s2-s3 | D12: 11_s2-s3 | E12: 0.1 | F12: sensitivity(not paper) | G12: svd | H12: 57 | I12: 51 | J12: 57 | K12: 51 | L12: 3 | M12: 8 | N12: 369 | O12: 17 | P12: 208 | Q12: 28 | R12: 18 | S12: 0 | T12: 0 | U12: 0 | V12: 0 | W12: 16 | X12: 16 | Y12: 0 | Z12: 1 | AA12: 2.00036 | AB12: 0.10939465 | AD12: 0 | AE12: 2.261734 | AF12: -0.91851505 | AG12: 0.39451307 | AH12: -0.026258918 | AI12: -0.39499256 | AJ12: -0.91853723 | AK12: 0.016438985 | AL12: -0.017634399 | AM12: 0.025471533 | AN12: 0.99952 | AO12: -1.5137353 | AP12: -3.740741 | AQ12: 0.20812189
A13: baseline | B13: 11 | C13: s2-s3 | D13: 11_s2-s3 | E13: 0.1 | F13: sensitivity(not paper) | G13: svd+ransac | H13: 57 | I13: 51 | J13: 57 | K13: 51 | L13: 3 | M13: 8 | N13: 369 | O13: 17 | P13: 208 | Q13: 28 | R13: 18 | S13: 0 | T13: 0 | U13: 0 | V13: 0 | W13: 16 | X13: 16 | Y13: 14 | Z13: 1 | AA13: 0.676017 | AB13: 0.029352326 | AD13: 1 | AE13: 3.165256 | AF13: -0.9189774 | AG13: 0.39426562 | AH13: -0.0059291085 | AI13: -0.39429457 | AJ13: -0.91897096 | AK13: 0.0049162263 | AL13: -0.0035103795 | AM13: 0.0068557162 | AN13: 0.99997034 | AO13: -1.46053 | AP13: -3.7748015 | AQ13: 0.15386127
... A39: baseline | B39: 12 | C39: s1-s5 | D39: 12_s1-s5 | E39: 0.1 | F39: sensitivity(not paper) | G39: svd+ransac | H39: 54 | I39: 88 | J39: 54 | K39: 88 | L39: 13 | M39: 14 | N39: 460 | O39: 12 | P39: 123 | Q39: 13 | R39: 11 | S39: 0 | T39: 0 | U39: 0 | V39: 0 | W39: 9 | X39: 9 | Y39: 9 | Z39: 1 | AA39: 0.57239351 | AB39: 0.094678168 | AD39: 1 | AE39: 3.697281 | AF39: 0.2246617 | AG39: -0.9744368 | AH39: 0.0001953484 | AI39: 0.97437373 | AJ39: 0.22464486 | AK39: -0.011424122 | AL39: 0.0110882 | AM39: 0.0027569049 | AN39: 0.99993472 | AO39: -16.524667 | AP39: 20.497024 | AQ39: 1.0829248
A40: baseline | B40: 12 | C40: s1-s6 | D40: 12_s1-s6 | E40: 0.1 | F40: sensitivity(not paper) | G40: svd | H40: 54 | I40: 82 | J40: 54 | K40: 82 | L40: 8 | M40: 14 | N40: 361 | O40: 8 | P40: 34 | Q40: 4 | R40: 3 | S40: 1 | T40: 4 | U40: 4 | V40: 0 | W40: 0 | X40: 0 | Y40: 0 | Z40: 0 | AD40: 0 | AE40: 3.066756 | AF40: 1 | AG40: 0 | AH40: 0 | AI40: 0 | AJ40: 1 | AK40: 0 | AL40: 0 | AM40: 0 | AN40: 1 | AO40: 0 | AP40: 0 | AQ40: 0
A41: baseline | B41: 12 | C41: s1-s6 | D41: 12_s1-s6 | E41: 0.1 | F41: sensitivity(not paper) | G41: svd+ransac | H41: 54 | I41: 82 | J41: 54 | K41: 82 | L41: 8 | M41: 14 | N41: 361 | O41: 8 | P41: 34 | Q41: 4 | R41: 3 | S41: 1 | T41: 4 | U41: 4 | V41: 0 | W41: 0 | X41: 0 | Y41: 0 | Z41: 0 | AD41: 0 | AE41: 3.066566 | AF41: 1 | AG41: 0 | AH41: 0 | AI41: 0 | AJ41: 1 | AK41: 0 | AL41: 0 | AM41: 0 | AN41: 1 | AO41: 0 | AP41: 0 | AQ41: 0
A42: baseline | B42: 12 | C42: s2-s3 | D42: 12_s2-s3 | E42: 0.1 | F42: sensitivity(not paper) | G42: svd | H42: 59 | I42: 47 | J42: 59 | K42: 47 | L42: 4 | M42: 10 | N42: 286 | O42: 16 | P42: 198 | Q42: 28 | R42: 17 | S42: 0 | T42: 0 | U42: 0 | V42: 0 | W42: 15 | X42: 15 | Y42: 0 | Z42: 1 | AA42: 1.3868504 | AB42: 0.13160352 | AD42: 1 | AE42: 1.598565 | AF42: -0.91914422 | AG42: 0.39357251 | AH42: -0.016570609 | AI42: -0.39377747 | AJ42: -0.91913179 | AK42: 0.011664078 | AL42: -0.010639914 | AM42: 0.017246102 | AN42: 0.99979466 | AO42: -1.4720722 | AP42: -3.7670644 | AQ42: 0.010016328
A43: baseline | B43: 12 | C43: s2-s3 | D43: 12_s2-s3 | E43: 0.1 | F43: sensitivity(not paper) | G43: svd+ransac | H43: 59 | I43: 47 | J43: 59 | K43: 47 | L43: 4 | M43: 10 | N43: 286 | O43: 16 | P43: 198 | Q43: 28 | R43: 17 | S43: 0 | T43: 0 | U43: 0 | V43: 0 | W43: 15 | X43: 15 | Y43: 14 | Z43: 1 | AA43: 0.36881896 | AB43: 0.057268447 | AD43: 1 | AE43: 2.420829 | AF43: -0.91942832 | AG43: 0.39325764 | AH43: -3.2775803e-05 | AI43: -0.39325622 | AJ43: -0.91942477 | AK43: 0.0027648262 | AL43: 0.0010571541 | AM43: 0.0025549488 | AN43: 0.99999618 | AO43: -1.4442397 | AP43: -3.7832973 | AQ43: 0.081963202
A44: baseline | B44: 12 | C44: s2-s4 | D44: 12_s2-s4 | E44: 0.1 | F44: sensitivity(not paper) | G44: svd | H44: 59 | I44: 57 | J44: 59 | K44: 57 | L44: 1 | M44: 7 | N44: 274 | O44: 13 | P44: 146 | Q44: 16 | R44: 13 | S44: 0 | T44: 0 | U44: 0 | V44: 0 | W44: 11 | X44: 11 | Y44: 0 | Z44: 1 | AA44: 0.53713641 | AB44: 0.030696717 | AD44: 1 | AE44: 1.767185 | AF44: -0.94763609 | AG44: 0.31934578 | AH44: -0.002028618 | AI44: -0.31930684 | AJ44: -0.94758938 | AK44: -0.010840208 | AL44: -0.0053840717 | AM44: -0.0096248211 | AN44: 0.99993919 | AO44: 12.640998 | AP44: 2.1739894 | AQ44: 0.85266949
A45: baseline | B45: 12 | C45: s2-s4 | D45: 12_s2-s4 | E45: 0.1 | F45: sensitivity(not paper) | G45: svd+ransac | H45: 59 | I45: 57 | J45: 59 | K45: 57 | L45: 1 | M45: 7 | N45: 274 | O45: 13 | P45: 146 | Q45: 16 | R45: 13 | S45: 0 | T45: 0 | U45: 0 | V45: 0 | W45: 11 | X45: 11 | Y45: 11 | Z45: 1 | AA45: 0.53713641 | AB45: 0.030696717 | AD45: 1 | AE45: 2.71565 | AF45: -0.94763609 | AG45: 0.31934578 | AH45: -0.002028618 | AI45: -0.31930684 | AJ45: -0.94758938 | AK45: -0.010840208 | AL45: -0.0053840717 | AM45: -0.0096248211 | AN45: 0.99993919 | AO45: 12.640998 | AP45: 2.1739894 | AQ45: 0.85266949
A46: baseline | B46: 12 | C46: s2-s5 | D46: 12_s2-s5 | E46: 0.1 | F46: sensitivity(not paper) | G46: svd | H46: 59 | I46: 88 | J46: 59 | K46: 88 | L46: 9 | M46: 16 | N46: 555 | O46: 14 | P46: 69 | Q46: 19 | R46: 5 | S46: 0 | T46: 0 | U46: 0 | V46: 0 | W46: 4 | X46: 4 | Y46: 0 | Z46: 1 | AA46: 0.97579348 | AB46: 0.038594445 | AD46: 1 | AE46: 3.366866 | AF46: 0.51973714 | AG46: 0.85413391 | AH46: 0.018126326 | AI46: -0.85423444 | AJ46: 0.51987532 | AK46: -0.0036286212 | AL46: -0.012522758 | AM46: -0.013598203 | AN46: 0.99982912 | AO46: -10.049835 | AP46: 11.45353 | AQ46: 0.4755858
A47: baseline | B47: 12 | C47: s2-s5 | D47: 12_s2-s5 | E47: 0.1 | F47: sensitivity(not paper) | G47: svd+ransac | H47: 59 | I47: 88 | J47: 59 | K47: 88 | L47: 9 | M47: 16 | N47: 555 | O47: 14 | P47: 69 | Q47: 19 | R47: 5 | S47: 0 | T47: 0 | U47: 0 | V47: 0 | W47: 4 | X47: 4 | Y47: 4 | Z47: 1 | AA47: 0.97579348 | AB47: 0.038594445 | AD47: 1 | AE47: 3.681463 | AF47: 0.51973714 | AG47: 0.85413391 | AH47: 0.018126326 | AI47: -0.85423444 | AJ47: 0.51987532 | AK47: -0.0036286212 | AL47: -0.012522758 | AM47: -0.013598203 | AN47: 0.99982912 | AO47: -10.049835 | AP47: 11.45353 | AQ47: 0.4755858
A48: baseline | B48: 12 | C48: s2-s6 | D48: 12_s2-s6 | E48: 0.1 | F48: sensitivity(not paper) | G48: svd | H48: 59 | I48: 82 | J48: 59 | K48: 82 | L48: 4 | M48: 16 | N48: 431 | O48: 12 | P48: 74 | Q48: 4 | R48: 7 | S48: 0 | T48: 0 | U48: 0 | V48: 0 | W48: 7 | X48: 7 | Y48: 0 | Z48: 1 | AA48: 2.6011556 | AB48: 0.22407278 | AD48: 0 | AE48: 2.590375 | AF48: -0.81178178 | AG48: 0.58258189 | AH48: -0.040108364 | AI48: -0.58338917 | AJ48: -0.8121104 | AK48: 0.011565986 | AL48: -0.025834286 | AM48: 0.032787842 | AN48: 0.99912839 | AO48: 16.573048 | AP48: 12.661636 | AQ48: 1.3408401
A49: baseline | B49: 12 | C49: s2-s6 | D49: 12_s2-s6 | E49: 0.1 | F49: sensitivity(not paper) | G49: svd+ransac | H49: 59 | I49: 82 | J49: 59 | K49: 82 | L49: 4 | M49: 16 | N49: 431 | O49: 12 | P49: 74 | Q49: 4 | R49: 7 | S49: 0 | T49: 0 | U49: 0 | V49: 0 | W49: 7 | X49: 7 | Y49: 6 | Z49: 1 | AA49: 0.75731466 | AB49: 0.05117237 | AD49: 1 | AE49: 3.209284 | AF49: -0.81273211 | AG49: 0.58254948 | AH49: -0.010130042 | AI49: -0.58257003 | AJ49: -0.81277978 | AK49: -0.0010921354 | AL49: -0.0088697158 | AM49: 0.0050138451 | AN49: 0.99994809 | AO49: 16.627449 | AP49: 12.641623 | AQ49: 1.5048611
A50: baseline | B50: 12 | C50: s3-s4 | D50: 12_s3-s4 | E50: 0.1 | F50: sensitivity(not paper) | G50: svd | H50: 47 | I50: 57 | J50: 47 | K50: 57 | L50: 3 | M50: 5 | N50: 171 | O50: 8 | P50: 104 | Q50: 14 | R50: 9 | S50: 0 | T50: 0 | U50: 0 | V50: 0 | W50: 6 | X50: 6 | Y50: 0 | Z50: 1 | AA50: 0.53958675 | AB50: 0.026632445 | AD50: 1 | AE50: 1.559448 | AF50: 0.99672728 | AG50: 0.080409042 | AH50: -0.0083129838 | AI50: -0.080378398 | AJ50: 0.99675657 | AK50: 0.003957377 | AL50: 0.0086042301 | AM50: -0.0032762413 | AN50: 0.99995762 | AO50: 14.362069 | AP50: 5.8354721 | AQ50: 0.72941321
A51: baseline | B51: 12 | C51: s3-s4 | D51: 12_s3-s4 | E51: 0.1 | F51: sensitivity(not paper) | G51: svd+ransac | H51: 47 | I51: 57 | J51: 47 | K51: 57 | L51: 3 | M51: 5 | N51: 171 | O51: 8 | P51: 104 | Q51: 14 | R51: 9 | S51: 0 | T51: 0 | U51: 0 | V51: 0 | W51: 6 | X51: 6 | Y51: 6 | Z51: 1 | AA51: 0.53958675 | AB51: 0.026632445 | AD51: 1 | AE51: 1.997748 | AF51: 0.99672728 | AG51: 0.080409042 | AH51: -0.0083129838 | AI51: -0.080378398 | AJ51: 0.99675657 | AK51: 0.003957377 | AL51: 0.0086042301 | AM51: -0.0032762413 | AN51: 0.99995762 | AO51: 14.362069 | AP51: 5.8354721 | AQ51: 0.72941321
A52: baseline | B52: 12 | C52: s3-s5 | D52: 12_s3-s5 | E52: 0.1 | F52: sensitivity(not paper) | G52: svd | H52: 47 | I52: 88 | J52: 47 | K52: 88 | L52: 11 | M52: 14 | N52: 383 | O52: 13 | P52: 110 | Q52: 20 | R52: 9 | S52: 0 | T52: 0 | U52: 0 | V52: 0 | W52: 8 | X52: 8 | Y52: 0 | Z52: 1 | AA52: 0.095482886 | AB52: 0.0330364 | AD52: 1 | AE52: 2.607799 | AF52: -0.13769324 | AG52: -0.99047463 | AH52: 0.00076508 | AI52: 0.99047162 | AJ52: -0.13769473 | AK52: -0.0024744892 | AL52: 0.0025562663 | AM52: 0.0004170696 | AN52: 0.99999665 | AO52: -14.022622 | AP52: 12.401658 | AQ52: 0.27909199
A53: baseline | B53: 12 | C53: s3-s5 | D53: 12_s3-s5 | E53: 0.1 | F53: sensitivity(not paper) | G53: svd+ransac | H53: 47 | I53: 88 | J53: 47 | K53: 88 | L53: 11 | M53: 14 | N53: 383 | O53: 13 | P53: 110 | Q53: 20 | R53: 9 | S53: 0 | T53: 0 | U53: 0 | V53: 0 | W53: 8 | X53: 8 | Y53: 8 | Z53: 1 | AA53: 0.095482886 | AB53: 0.0330364 | AD53: 1 | AE53: 3.229781 | AF53: -0.13769324 | AG53: -0.99047463 | AH53: 0.00076508 | AI53: 0.99047162 | AJ53: -0.13769473 | AK53: -0.0024744892 | AL53: 0.0025562663 | AM53: 0.0004170696 | AN53: 0.99999665 | AO53: -14.022622 | AP53: 12.401658 | AQ53: 0.27909199
... A97: baseline | B97: 14 | C97: s1-s4 | D97: 14_s1-s4 | E97: 0.1 | F97: sensitivity(not paper) | G97: svd+ransac | H97: 53 | I97: 59 | J97: 53 | K97: 59 | L97: 7 | M97: 6 | N97: 267 | O97: 11 | P97: 76 | Q97: 16 | R97: 6 | S97: 0 | T97: 0 | U97: 0 | V97: 0 | W97: 5 | X97: 5 | Y97: 5 | Z97: 1 | AA97: 1.0020328 | AB97: 0.21067835 | AD97: 1 | AE97: 2.408336 | AF97: 0.90277389 | AG97: 0.42985774 | AH97: -0.014887403 | AI97: -0.42999443 | AJ97: 0.90280013 | AK97: -0.007531048 | AL97: 0.01020307 | AM97: 0.013200334 | AN97: 0.99986081 | AO97: 22.80228 | AP97: 6.5309203 | AQ97: 1.6029176
A98: baseline | B98: 14 | C98: s1-s5 | D98: 14_s1-s5 | E98: 0.1 | F98: sensitivity(not paper) | G98: svd | H98: 53 | I98: 89 | J98: 53 | K98: 89 | L98: 7 | M98: 14 | N98: 413 | O98: 9 | P98: 43 | Q98: 13 | R98: 3 | S98: 0 | T98: 0 | U98: 0 | V98: 0 | W98: 1 | X98: 1 | Y98: 0 | Z98: 0 | AD98: 0 | AE98: 2.846351 | AF98: 1 | AG98: 0 | AH98: 0 | AI98: 0 | AJ98: 1 | AK98: 0 | AL98: 0 | AM98: 0 | AN98: 1 | AO98: 0 | AP98: 0 | AQ98: 0
A99: baseline | B99: 14 | C99: s1-s5 | D99: 14_s1-s5 | E99: 0.1 | F99: sensitivity(not paper) | G99: svd+ransac | H99: 53 | I99: 89 | J99: 53 | K99: 89 | L99: 7 | M99: 14 | N99: 413 | O99: 9 | P99: 43 | Q99: 13 | R99: 3 | S99: 0 | T99: 0 | U99: 0 | V99: 0 | W99: 1 | X99: 1 | Y99: 0 | Z99: 0 | AD99: 0 | AE99: 2.845982 | AF99: 1 | AG99: 0 | AH99: 0 | AI99: 0 | AJ99: 1 | AK99: 0 | AL99: 0 | AM99: 0 | AN99: 1 | AO99: 0 | AP99: 0 | AQ99: 0
A100: baseline | B100: 14 | C100: s1-s6 | D100: 14_s1-s6 | E100: 0.1 | F100: sensitivity(not paper) | G100: svd | H100: 53 | I100: 91 | J100: 53 | K100: 91 | L100: 9 | M100: 8 | N100: 368 | O100: 8 | P100: 28 | Q100: 8 | R100: 2 | S100: 1 | T100: 6 | U100: 6 | V100: 10 | W100: 5 | X100: 5 | Y100: 0 | Z100: 1 | AA100: 3.6574011 | AB100: 0.21096124 | AD100: 0 | AE100: 3.454547 | AF100: 0.98716501 | AG100: 0.15266419 | AH100: -0.046892296 | AI100: -0.15084555 | AJ100: 0.9877412 | AK100: 0.040161348 | AL100: 0.052448652 | AM100: -0.032572383 | AN100: 0.99809227 | AO100: 25.08119 | AP100: 19.874749 | AQ100: 2.2757799
A101: baseline | B101: 14 | C101: s1-s6 | D101: 14_s1-s6 | E101: 0.1 | F101: sensitivity(not paper) | G101: svd+ransac | H101: 53 | I101: 91 | J101: 53 | K101: 91 | L101: 9 | M101: 8 | N101: 368 | O101: 8 | P101: 28 | Q101: 8 | R101: 2 | S101: 1 | T101: 6 | U101: 6 | V101: 10 | W101: 5 | X101: 5 | Y101: 4 | Z101: 1 | AA101: 1.1687845 | AB101: 0.069509843 | AD101: 1 | AE101: 3.913259 | AF101: 0.98861015 | AG101: 0.14936373 | AH101: -0.018451225 | AI101: -0.14932864 | AJ101: 0.9887822 | AK101: 0.0032731329 | AL101: 0.01873313 | AM101: -0.00048055611 | AN101: 0.9998244 | AO101: 25.134979 | AP101: 19.808878 | AQ101: 2.1516177
A102: baseline | B102: 14 | C102: s2-s3 | D102: 14_s2-s3 | E102: 0.1 | F102: sensitivity(not paper) | G102: svd | H102: 59 | I102: 52 | J102: 59 | K102: 52 | L102: 5 | M102: 9 | N102: 336 | O102: 15 | P102: 143 | Q102: 13 | R102: 13 | S102: 0 | T102: 0 | U102: 0 | V102: 0 | W102: 11 | X102: 11 | Y102: 0 | Z102: 1 | AA102: 1.1607869 | AB102: 0.1501446 | AD102: 1 | AE102: 1.76362 | AF102: -0.91946377 | AG102: 0.3929716 | AH102: -0.012637226 | AI102: -0.39310158 | AJ102: -0.91943774 | AK102: 0.010266342 | AL102: -0.0075847617 | AM102: 0.014407243 | AN102: 0.99986744 | AO102: -1.4610985 | AP102: -3.7614549 | AQ102: -0.0088676716
